Workbook

Sheet Home Page
B1: Battle Dome 4.4 Home Page
B3: Ability Resources
B4: Archer | C4: Clairvoyant | D4: Dark | E4: Dueler | F4: Heavy | G4: Noble | H4: Sorcerer | I4: Trophy
B5: Classes | D5: BETA | F5: Stats | H5: Loot Table
B6: Items
B7: Main (Stay tuned!) | E7: PvE | G7: Legacy PvE | I7: 1vE
B8: Other Resources
B9: 4.4 Host Guide | F9: Glossary
B10: How to Play | F10: Changelog
A11: You have lost The Game | J11: kry stinks

Sheet BETA
B2: BETA
B3: Beta is for content in a testing phase. To host beta content, users must ask for special permission to host, and you can use the highlight word betasignup. Beta games are looted as normal. To discuss feedback, feel free to use the BD Discord. Additions to Beta must have a chance of being added and require the endorsement of a staff member. Beta content exists by default for 1 month. This may be extended as long as the content is being developed or tested. Beta games go in groupchats.
B4: Date Added | C4: Change | D4: Created by | E4: Approved by | F4: Last Edited | G4: Last Reviewed
B5: 46210 | C5: Beta Items | D5: ThrohOrFalse | E5: ThrohOrFalse | F5: 46210 | G5: 46210
B6: 46211 | C6: Banner | D6: Ocean | E6: Ocean | F6: 46211 | G6: 46211
B7: 46223 | C7: Longbow Rework | D7: Salient | E7: Elissem

Sheet Classes
A1: Name | B1: Lv. | C1: Frequency | D1: MR | E1: Damage | H1: Target | K1: Effect
E2: Roll | F2: Type | G2: Action | H2: Amount | I2: Group | J2: Range
A3: Basic Abilities
A4: Basic Attack | B4: B | C4: Every Turn | D4: 2 | E4: 1d10+2 | F4: Physical or Magical | G4: Standard | H4: 1 | I4: Foe | J4: Melee | K4: This attack is either Physical or Magical. Add ATK/MAG to the damage roll and subtract the target's PD/MD. This move's use cannot be prevented by any means, including Seal.
A5: Basic Movement | B5: B | C5: Every Turn | D5: - | E5: - | F5: - | G5: Movement | H5: - | I5: Self | J5: - | K5: The user spends MP to move an equal amount of tiles. (For all purposes, Basic Movement is not an ability, but is still an action.)
A6: Dash | B6: B | C6: Every Turn | D6: - | E6: - | F6: - | G6: Full | H6: - | I6: Self | J6: - | K6: The user spends MP to move up to x1.5 that amount of tiles (rounded down).
A7: Backstep | B7: B | C7: Passive | D7: - | E7: - | F7: - | G7: - | H7: - | I7: Self | J7: - | K7: During the user's Movement/Full action, the user has unremovable -2 MP for the rest of the turn after leaving a foe's Melee.
A8: Attack of Opportunity | B8: B | C8: Every Turn | D8: 2 | E8: 1d10+2 | F8: Physical or Magical | G8: Reaction | H8: 1 | I8: Foe | J8: Melee | K8: This may be used on a foe in the user's Melee that either: 1. uses a ranged attack that doesn't target the user (after damage is rolled) or 2. leaves the user's Melee using Dash. (AoO still adds ATK/MAG and DEF.)
A9: Class Abilities
A11: Bard (Taistelu, Felucia)
A12: =Stats!A4 & " HP | " & Stats!B4 & " ATK | " & Stats!C4 & " MAG | " & Stats!D4 & " PDEF | " & Stats!E4 & " MDEF | " & Stats!F4 & " EVA | " & Stats!G4 & " MP " -> 80 HP | 7 ATK | 7 MAG | 0 PDEF | 0 MDEF | 1.7 EVA | 3 MP | G12: "A support class that links to an ally to maximise the impact of their class abilities."
A13: Duet | B13: 1 | C13: Every Turn | D13: - | E13: - | F13: - | G13: Free | H13: 1 | I13: Ally | J13: Global | K13: Apply Duet to one player. Bard abilities also originate from that player and consider them an ally. The user may also use this ability to end their Duet. Effects stack on targets in the overlap; Bard attack targets take an additional hit that uses the same accuracy roll.
A14: Rising Hope | B14: 1 | C14: Passive | D14: - | E14: - | F14: - | G14: - | H14: AoE | I14: Self and Allies | J14: Burst 1 | K14: The user and allies within range have +1 ACC and CR. Players can benefit from a maximum of 2 Rising Hopes at a time.
A15: Dissonance | B15: 2 | C15: EoT | D15: 3 | E15: 2d6+0 | F15: Magical | G15: Swift | H15: AoE | I15: Foes | J15: Cone 2 | K15: Inflict 3 Bleed/1. This attack's hits ignore ATK/MAG, half foes' DEF, and outside damage factors. Damage on targets hit twice is increased by 3 for one round.
A16: Primadonna | B16: 3 | C16: Twice/E3T | D16: - | E16: - | F16: - | G16: Free | H16: AoE | I16: Self and Allies | J16: Star 4 | K16: If the player this ability originates from has more MAG than ATK, target's gain +4 MAG/1 and -3 MDEF/1; otherwise, targets gain +4 ATK/1 and -3 MDEF/1. Targets whose ATK and MAG are buffed by this also gain +1 damage dice/1, which doubles on critical hits.
A17: Fantasia | B17: 4 | C17: Thrice/EoT | D17: - | E17: - | F17: - | G17: Free | H17: 1 | I17: Self | J17: - | K17: Select a bonus: +3 ATK/MAG, +1 ACC/CR, +4 DEF. Until the start of the user's next turn, Rising Hope becomes Star 2 and additionally grants the bonuses selected during this and prior uses of Fantasia. The user may not pick the same bonus more than once.
A18: Staccato | B18: 5 | C18: Once | D18: 2 | E18: 1d6+0 | F18: - | G18: Reaction | H18: 1 | I18: Foe | J18: Global | K18: This may be used when a foe attacks the user or their Duet ally, after damage is rolled. Apply hits to the target and foes within Star 2 of the user and Duet ally. Each hit inflicts -2 DEF/1 and -1 EVA/1. If the attacker kills the Duet ally, the user gains a permanent +2 MP, ACC and CR. This attack ignores outside damage factors.
A19: Blacksmith (Methridium)
A20: =Stats!H4 & " HP | " & Stats!I4 & " ATK | " & Stats!J4 & " MAG | " & Stats!K4 & " PDEF | " & Stats!L4 & " MDEF | " & Stats!M4 & " EVA | " & Stats!N4 & " MP " -> 65 HP | 9 ATK | 8 MAG | 4 PDEF | 6 MDEF | 0.9 EVA | 3 MP | G20: "A specialist in trapping and area denial; corner your foes, or make them regret approaching you."
A21: Ironclad | B21: 1 | C21: Passive | D21: - | E21: - | F21: - | G21: - | H21: - | I21: - | J21: - | K21: When an attack deals 40+ damage to the user, the attacker is inflicted with 2 Cripple/1; if 55+ (before this effect), 10% of its damage is nullified, and dealt back to the attacker.
A22: Mantrap | B22: 1 | C22: Thrice/EoT | D22: - | E22: - | F22: - | G22: Free | H22: 1 | I22: Tile | J22: Homing 5 | K22: When a foe ends their turn within or willingly enters the targeted tile's Star 1, the user may, as a Reaction, inflict them with 3 Cripple/1 and -4 DMG/1, removing this effect.
A23: Smokescreen | B23: 2 | C23: E3T | D23: - | E23: - | F23: - | G23: Free | H23: - | I23: Self | J23: - | K23: Until the start of the user's next turn, all attacks entering the user's Burst 2 have -2 Range and -7 DMG, and attacks used within the user's Burst 2 have -2 Range.
A24: Tinker's Dam | B24: 3 | C24: Once | D24: - | E24: - | F24: - | G24: Swift | H24: 1 | I24: Tile | J24: Range 3 | K24: The user creates a wall of Stone on unoccupied tiles on the target and its Line 2 in a chosen direction, which is removed after 2 rounds, or can be removed on the user's turn as a Free action. Foes ending their turn with any of these Stone tiles in their melee take 5 damage and are Burned 3/1. Stone tiles function like Ice, but take 30 damage to break and have 1 EVA.
A25: Reforge | B25: 4 | C25: E3T | D25: - | E25: - | F25: - | G25: Movement | H25: 1 | I25: Foe or Ally | J25: Melee | K25: Choose one of the target's base stats, except HP. If the target is a foe, reduce the chosen base stat by 1/3 for one round, and the target cannot receive buffs to that stat while under this effect. If the target is an ally, the chosen base stat is 1.5x for one round.
A26: Mending Mantel | B26: 5 | C26: Once | D26: - | E26: - | F26: - | G26: Full | H26: 1 | I26: Tile | J26: Homing 3 | K26: Place a Hearth tile on the target. Hearth tiles give +5 DEF/1 and 5 HP in healing to the user and allies whenever they end their turn in its Star 3 (ignoring Foe obstructions). Hearth tiles also have the effects of Stone, and are removed when the user dies.
A27: Cleric (Ocean, Vrji)
A28: =Stats!O4 & " HP | " & Stats!P4 & " ATK | " & Stats!Q4 & " MAG | " & Stats!R4 & " PDEF | " & Stats!S4 & " MDEF | " & Stats!T4 & " EVA | " & Stats!U4 & " MP " -> 55 HP | 7 ATK | 10 MAG | 2 PDEF | 4 MDEF | 0.6 EVA | 3 MP | G28: "A naturally frail class dedicated to healing and supporting its allies."
A29: First Aid | B29: 1 | C29: EoT | D29: - | E29: 3d4+6 | F29: - | G29: Swift | H29: 1 | I29: Self or Ally | J29: Range 3 | K29: The target is healed the rolled amount. If the target is an ally, this may be used as a Standard action to add the user's ATK or MAG to the roll. This can only be used on a target that has been attacked in the last round.
A30: Ward | B30: 2 | C30: E3T | D30: - | E30: - | F30: - | G30: Swift | H30: AoE | I30: Self and Allies | J30: Burst 2 | K30: Targets cannot be inflicted with debuffs or statuses for one round.
A31: Heaven's Wind | B31: 3 | C31: EoT | D31: - | E31: - | F31: - | G31: Swift | H31: 2 | I31: Any | J31: Range 4 | K31: The targets teleport and swap locations.
A32: Martyrdom | B32: 4 | C32: E3T | D32: - | E32: - | F32: - | G32: Free | H32: - | I32: Self | J32: - | K32: For one round, the user's healing is increased by 15% and players who are healed by their moves receive +1 EVA/MP (max +3) until the start of the user's next turn. For each ally that has died, this healing bonus is increased by 15%.
A33: Vestments | B33: 5 | C33: Twice | D33: - | E33: - | F33: - | G33: Free | H33: 1 | I33: Self or Ally | J33: Range 4 | K33: Choose one primary target and one secondary target (they can be the same player). For one round, the primary target heals 1/4 of the damage taken by the secondary target. The primary target can only be Self if two uses of this move are available; it then uses up two uses. Players can only be the primary target of one Vestments at a time.
A34: Dancer (Ocean, Taistelu)
A35: =Stats!V4 & " HP | " & Stats!W4 & " ATK | " & Stats!X4 & " MAG | " & Stats!Y4 & " PDEF | " & Stats!Z4 & " MDEF | " & Stats!AA4 & " EVA | " & Stats!AB4 & " MP " -> 70 HP | 11 ATK | 10 MAG | 2 PDEF | 4 MDEF | 1.6 EVA | 3 MP | G35: "An offensive support class with mastery over the turn order and action economy."
A36: Pas de Deux | B36: 1 | C36: E3T | D36: - | E36: - | F36: - | G36: Standard or Full | H36: 1 | I36: Ally | J36: Melee | K36: The target immediately takes their turn after the user. Then, turn order resumes as normal. The target cannot use Pas de Deux on the given turn. If the target is a Juggernaut, they only have access to one Standard. If this is used as a Standard, the target cannot use their Movement action.
A37: Emboîté | B37: 2 | C37: Once | D37: - | E37: - | F37: - | G37: Swift | H37: AoE | I37: Self and Allies | J37: Burst 1 | K37: The targets' abilities that are on cooldown may be used one round earlier. (E3T becomes EoT; EoT becomes Every Turn, etc.)
A38: Fouetté | B38: 3 | C38: Once | D38: - | E38: - | F38: - | G38: Swift | H38: 1 | I38: Self or Ally | J38: Range 3 | K38: Until the start of the user's next turn, the target may use one Once/Twice/Thrice move without expending a Use, even if the move is out of Uses. This cannot be used on Reaction or Trigger actions.
A39: En Pointe | B39: 4 | C39: Passive | D39: - | E39: - | F39: - | G39: - | H39: - | I39: - | J39: - | K39: The user may use their Class and Item Swift actions as if they are Frees. Whenever the user targets an ally with a Dancer action, they gain a copy of this passive until the end of their next turn.
A40: Divertissement | B40: 5 | C40: Once | D40: - | E40: - | F40: - | G40: Swift | H40: 1 | I40: Self or Ally | J40: Range 3 | K40: The target's next Standard/Full attack on their next turn gains +dice faces equal to the number of actions previously used that turn (except Basic Movement), max +5 dice faces. This ability’s action type is unaffected by En Pointe.
A41: Monk (Ocean, Vrji)
...

Sheet Archer
A1: Name | B1: Lv. | C1: Frequency | D1: MR | E1: Damage | H1: Target | K1: Effect
E2: Roll | F2: Type | G2: Action | H2: Amount | I2: Group | J2: Range
A3: Basic Abilities
A4: =Classes!A4 -> Basic Attack | B4: =Classes!B4 -> B | C4: =Classes!C4 -> Every Turn | D4: =Classes!D4 -> 2 | E4: =Classes!E4 -> 1d10+2 | F4: =Classes!F4 -> Physical or Magical | G4: =Classes!G4 -> Standard | H4: =Classes!H4 -> 1 | ... K4: =Classes!K4 -> This attack is either Physical or Magical. Add ATK/MAG to the damage roll and subtract the target's PD/MD. This move's use cannot be prevented by any means, including Seal.
A5: =Classes!A5 -> Basic Movement | B5: =Classes!B5 -> B | C5: =Classes!C5 -> Every Turn | D5: =Classes!D5 -> - | E5: =Classes!E5 -> - | F5: =Classes!F5 -> - | G5: =Classes!G5 -> Movement | H5: =Classes!H5 -> - | ... K5: =Classes!K5 -> The user spends MP to move an equal amount of tiles. (For all purposes, Basic Movement is not an ability, but is still an action.)
A6: =Classes!A6 -> Dash | B6: =Classes!B6 -> B | C6: =Classes!C6 -> Every Turn | D6: =Classes!D6 -> - | E6: =Classes!E6 -> - | F6: =Classes!F6 -> - | G6: =Classes!G6 -> Full | H6: =Classes!H6 -> - | ... K6: =Classes!K6 -> The user spends MP to move up to x1.5 that amount of tiles (rounded down).
A7: =Classes!A7 -> Backstep | B7: =Classes!B7 -> B | C7: =Classes!C7 -> Passive | D7: =Classes!D7 -> - | E7: =Classes!E7 -> - | F7: =Classes!F7 -> - | G7: =Classes!G7 -> - | H7: =Classes!H7 -> - | ... K7: =Classes!K7 -> During the user's Movement/Full action, the user has unremovable -2 MP for the rest of the turn after leaving a foe's Melee.
A8: =Classes!A8 -> Attack of Opportunity | B8: =Classes!B8 -> B | C8: =Classes!C8 -> Every Turn | D8: =Classes!D8 -> 2 | E8: =Classes!E8 -> 1d10+2 | F8: =Classes!F8 -> Physical or Magical | G8: =Classes!G8 -> Reaction | H8: =Classes!H8 -> 1 | ... K8: =Classes!K8 -> This may be used on a foe in the user's Melee that either: 1. uses a ranged attack that doesn't target the user (after damage is rolled) or 2. leaves the user's Melee using Dash. (AoO still adds ATK/MAG and DEF.)
A9: Archer Abilities
A11: Crossbow (Zuko743, Elissem)
A12: =Stats!A9 & " HP | " & Stats!B9 & " ATK | " & Stats!C9 & " MAG | " & Stats!D9 & " PDEF | " & Stats!E9 & " MDEF | " & Stats!F9 & " EVA | " & Stats!G9 & " MP " -> 65 HP | 15 ATK | 10 MAG | 3 PDEF | 3 MDEF | 1 EVA | 2 MP | G12: "A weapon with increased effectiveness the more you hunt an enemy down."
A13: Hunter's Mark | B13: 1 | C13: Passive | D13: - | E13: - | F13: - | G13: - | H13: - | I13: - | J13: - | K13: When the user's Crossbow attack resolves, targets of that attack each gain one Mark. The user's attacks deal +1d4 damage for every Mark on any one of its targets. Marks only apply to their user's abilities.
A14: Arrow Flurry | B14: 1 | C14: Every Turn | D14: 3 | E14: 2d8+7 | F14: Physical | G14: Standard | H14: 1 | I14: Foe | J14: Range 6 | K14: If the original target has a Mark, this move has Splash 1. If the target has 3+ Marks, this move instead has Splash 2.
A15: Cursed Bolts | B15: 2 | C15: EoT | D15: 3 | E15: 2d8+4 | F15: Magical | G15: Standard | H15: 1 | I15: Foe | J15: Line 6 | K15: The target is inflicted with 3X Curse/1, where X is Marks on the target. If the target has 3+ Marks, this move ignores negative outside damage factors.
A16: Arrow Net | B16: 3 | C16: E3T | D16: 4 | E16: 3d8+4 | F16: Physical | G16: Standard | H16: 1 | I16: Foe | J16: Range 6 | K16: Before damage, the target takes 3 damage every time they gain a Mark from the user for one round.
A17: Pierce | B17: 4 | C17: EoT | D17: 5 | E17: 2d8+5 | F17: Physical | G17: Standard | H17: AoE | I17: Foes | J17: Pierce 6 | K17: If a target has 1+ Marks, this move ignores evasions and 1/4 DEF. If a target has 2+ Marks, this move also ignores negative accuracy modifiers and ignores 1/2 DEF instead.
A18: Bolt Compaction | B18: 5 | C18: Twice/EoT | D18: - | E18: - | F18: - | G18: Free | H18: 1 | I18: Self | J18: - | K18: This turn, the user negates the secondary effects of their Standard Crossbow attacks. Next turn, regardless of if the negated attack hit, their first Standard attack has +1 dice and the negated effects.
A19: Quick Scope | B19: 5 | C19: Twice/EoT | D19: 3 | E19: 1d4+4 | F19: Physical | G19: Swift | H19: 1 | I19: Foe | J19: Range 6 | K19: This move ignores ATK/MAG, half of the target's DEF, and outside damage factors (except Hunter's Mark).
A20: Explosive Shot | B20: 6 | C20: Once | D20: 4 | E20: 2d8+2 | F20: Physical | G20: Standard | H20: 1 | I20: Foe | J20: Range 6 | K20: The target holds a "Bomb". If a foe with a Bomb targets another foe (including their allies) they transfer the Bomb to one of their targets. After one round or when the holder dies, the Bomb detonates and deals Xd4 Bomb damage to foes in the Bomb's Burst 1. X = the foe who held the Bomb with the most Marks.
A21: Tornado Bolt | B21: 7 | C21: Twice/EoT | D21: 4 | E21: 1d8+4 | F21: Magical | G21: Standard | H21: 1 | I21: Foe | J21: Line 6 | K21: This move has Push X equal to 1 + # of Marks on the target. If the target cannot be pushed the full distance, they gain +1 Mark.
A22: Shadow Quiver | B22: 8 | C22: Once | D22: - | E22: - | F22: - | G22: Swift | H22: - | I22: Self | J22: - | K22: The user's next standard attack becomes Magical, treats non-player obstructions as Air tiles, and ignores non-targets. This attack loses 2 damage per Air tile passed through.
A23: Serrated Arrows | B23: 9 | C23: Twice/E3T | D23: 4 | E23: 2d8+5 | F23: Physical | G23: Standard | H23: 1 | I23: Foe | J23: Range 6 | K23: The target is inflicted with X Bleed/1 equal to half of the damage from this attack's Hunter's Mark.
A24: Final Hour | B24: 10 | C24: Once | D24: - | E24: - | F24: - | G24: Free | H24: 1 | I24: Self | J24: - | K24: On the user's next attack, Hunter's Mark has +4 dice faces.
A25: Bolt Arsenal | B25: EX1 | C25: Every Turn | D25: - | E25: - | F25: - | G25: Trigger | H25: - | I25: Self | J25: - | K25: When they use a single-target Standard Crossbow attack, the user chooses one Bolt: Bounty Bolt: The target additionally gains half the Marks of the latest foe that died. Split-Head Bolt: The attack targets another foe, but loses Splash. Reeling Bolt: The target is pulled to a tile in the user's Line 3-6 (in the direction of the attack). These Bolts can only be used once until refresh. As a Swift action, refresh these Bolts.
A26: Quiver of Thunder | B26: EX2 | C26: Once | D26: - | E26: - | F26: - | G26: Free | H26: AoE | I26: Foes | J26: Global | K26: For one round, foes can only target entities in their Line 8. If they attack the user in Melee, they gain +1 Mark.
A27: Longbow (Salient, Felucia)
A28: =Stats!A11 & " HP | " & Stats!B11 & " ATK | " & Stats!C11 & " MAG | " & Stats!D11 & " PDEF | " & Stats!E11 & " MDEF | " & Stats!F11 & " EVA | " & Stats!G11 & " MP " -> 60 HP | 19 ATK | 13 MAG | 0 PDEF | 2 MDEF | 0.6 EVA | 0 MP | G28: "A magical bow with massive range and a few tricks up its sleeve for melee combat."
A29: Bound Bow | B29: 1 | C29: Passive | D29: - | E29: - | F29: - | G29: - | H29: - | I29: - | J29: - | K29: The user's Physical attacks become Magical when they target at least one entity at Range 3+. Once per turn, when the user attacks at Range 1-2, the user gains +3 DEF/1.
A30: Swift Shot | B30: 1 | C30: Every Turn | D30: 3 | E30: 2d10+7 | F30: Physical | G30: Standard | H30: 1 | I30: Foe | J30: Range 10 | K30: If the target is at Range 7+, this move critical hits on 14+. If the target is at under Range 3, gain +1 MP for 2 rounds.
A31: Crippling Shot | B31: 2 | C31: Every Turn | D31: 3 | E31: 2d8+5 | F31: Physical | G31: Standard | H31: 1 | I31: Foe | J31: Range 10 | K31: This move's effect changes based on the Range it is used on. 1-2: This move inflicts Slow/1. 3+: This move inflicts 2 Cripple/1 on accuracy rolls of 14+. 7+: This move inflicts Cripple regardless of accuracy.
A32: Blessed Arrow | B32: 3 | C32: Every Turn | D32: 3 | E32: 2d10+2 | F32: Physical | G32: Standard | H32: 1 | I32: Foe | J32: Range 10 | K32: For one round, all healing and buffs received or given by allies (including self) within Star 2 of the target is increased by x1.25, and any debuffs given to foes within Star 2 of the target are increased by x1.25 (these effects do not stack). As a non-damaging Standard, this move is 1/Tile/Range 10.
A33: Scatter Shot | B33: 4 | C33: EoT | D33: 4 | E33: 2d10+5 | F33: Physical | G33: Standard | H33: 1 or AoE | I33: Foe(s) | J33: Range 10 or Burst 1 | K33: If the original target is at Range 7+, this move gains Splash 1.
A34: Dispell Bow | B34: 5 | C34: E3T | D34: - | E34: - | F34: - | G34: Free | H34: 1 | I34: Self | J34: - | K34: This turn, the user has +2 MP and the user's ranged attacks have their Range reduced to 3 . Next turn, the user has +1 MP and the user's ranged attacks have their Range reduced to 6.
A35: Arcane Shot | B35: 6 | C35: Twice/EoT | D35: 5 | E35: 3d10+6 | F35: Magical | G35: Standard | H35: 1 | I35: Foe | J35: Range 10 | K35: If the target is at under Range 3, this move has Push 3. If the target is at Range 7+, this move ignores up to 10 DEF.
A36: Chase Arrow | B36: 7 | C36: Twice/EoT | D36: 3 | E36: 1d10+5 | F36: Physical | G36: Standard | H36: 1 | I36: Foe | J36: Homing 10 | K36: Targets must be within 8 tiles of the user. This move may target any foes on the path towards the original target, so long as the path taken doesn't exceed the move's range. Damage to these foes does not add ATK/MAG and ignores DEF.
A37: Volley | B37: 8 | C37: Twice/EoT | D37: 4 | E37: 1d10+5 (Double Hit) | F37: Physical | G37: Standard | H37: 1 | I37: Foe | J37: Range 10 | K37: If the target is 7+ tiles away this move gains +1 hit, if there are any foes within Splash 1 of the original target, this move gains an additional +2 hits. These bonus hits each target a random foe (including ice/stone tiles) in Splash 1 from the original target (including the original target), each apply half of the targets' DEF, and do not add ATK/MAG.
A38: Fireworks | B38: 9 | C38: Once | D38: 5 | E38: 4d8+4 | F38: Physical | G38: Standard | H38: 1 | I38: Foe | J38: Range 10 | K38: If the target is at Range 7+, this move has Bomb dice. If the target is under Range 3, before damage, Bound Bow's bonuses become +5 DEF/1 and +1 MP/1 until the user attacks at Range 3+.
A39: Sniper's Focus | B39: 10 | C39: Every Turn | D39: - | E39: - | F39: - | G39: Trigger | H39: - | I39: Self | J39: - | K39: This turn, the user's Standard actions are Full actions and their Range 7+ effects trigger at Range 4+.
A40: Bound Gauntlet | B40: EX1 | C40: Passive | D40: - | E40: - | F40: - | G40: - | H40: - | I40: Self | J40: - | K40: After dealing damage with a physical attack, deal magic damage equal to the damage (after subtracting DEF) to a different enemy in Melee range (if one exists). After dealing damage with a magical attack, your next physical attack ignores 5 DEF and cannot miss.
A41: Tactical Sniper | B41: EX2 | C41: Passive | D41: - | E41: - | F41: - | G41: - | H41: - | I41: Self | J41: - | K41: At the start of the game, designate one foe as the Bounty. Attacks against the Bounty treat obstructions as Air tiles and have +1 range. Melee attacks against the Bounty gain +1 dice. When the Bounty dies, immediately designate a new Bounty.
...

Sheet Clairvoyant
A1: Name | B1: Lv. | C1: Frequency | D1: MR | E1: Damage | H1: Target | K1: Effect
E2: Roll | F2: Type | G2: Action | H2: Amount | I2: Group | J2: Range
A3: Basic Abilities
A4: =Classes!A4 -> Basic Attack | B4: =Classes!B4 -> B | C4: =Classes!C4 -> Every Turn | D4: =Classes!D4 -> 2 | E4: =Classes!E4 -> 1d10+2 | F4: =Classes!F4 -> Physical or Magical | G4: =Classes!G4 -> Standard | H4: =Classes!H4 -> 1 | ... K4: =Classes!K4 -> This attack is either Physical or Magical. Add ATK/MAG to the damage roll and subtract the target's PD/MD. This move's use cannot be prevented by any means, including Seal.
A5: =Classes!A5 -> Basic Movement | B5: =Classes!B5 -> B | C5: =Classes!C5 -> Every Turn | D5: =Classes!D5 -> - | E5: =Classes!E5 -> - | F5: =Classes!F5 -> - | G5: =Classes!G5 -> Movement | H5: =Classes!H5 -> - | ... K5: =Classes!K5 -> The user spends MP to move an equal amount of tiles. (For all purposes, Basic Movement is not an ability, but is still an action.)
A6: =Classes!A6 -> Dash | B6: =Classes!B6 -> B | C6: =Classes!C6 -> Every Turn | D6: =Classes!D6 -> - | E6: =Classes!E6 -> - | F6: =Classes!F6 -> - | G6: =Classes!G6 -> Full | H6: =Classes!H6 -> - | ... K6: =Classes!K6 -> The user spends MP to move up to x1.5 that amount of tiles (rounded down).
A7: =Classes!A7 -> Backstep | B7: =Classes!B7 -> B | C7: =Classes!C7 -> Passive | D7: =Classes!D7 -> - | E7: =Classes!E7 -> - | F7: =Classes!F7 -> - | G7: =Classes!G7 -> - | H7: =Classes!H7 -> - | ... K7: =Classes!K7 -> During the user's Movement/Full action, the user has unremovable -2 MP for the rest of the turn after leaving a foe's Melee.
A8: =Classes!A8 -> Attack of Opportunity | B8: =Classes!B8 -> B | C8: =Classes!C8 -> Every Turn | D8: =Classes!D8 -> 2 | E8: =Classes!E8 -> 1d10+2 | F8: =Classes!F8 -> Physical or Magical | G8: =Classes!G8 -> Reaction | H8: =Classes!H8 -> 1 | ... K8: =Classes!K8 -> This may be used on a foe in the user's Melee that either: 1. uses a ranged attack that doesn't target the user (after damage is rolled) or 2. leaves the user's Melee using Dash. (AoO still adds ATK/MAG and DEF.)
A9: Clairvoyant Abilities
A11: Cards (Felucia / beautifications)
A12: =Stats!H9 & " HP | " & Stats!I9 & " ATK | " & Stats!J9 & " MAG | " & Stats!K9 & " PDEF | " & Stats!L9 & " MDEF | " & Stats!M9 & " EVA | " & Stats!N9 & " MP " -> 60 HP | 5 ATK | 8 MAG | 4 PDEF | 7 MDEF | 1.1 EVA | 2 MP | G12: "A high variance weapon that rewards the fortunate."
A13: Card Flip | B13: 1 | C13: Every Turn | D13: 3 | E13: 3d8+5 | F13: Magical | G13: Standard | H13: 1 | I13: Foe | J13: Range 4 | K13: Roll a d3 after rolling damage. If a 1 is rolled, this move deals 0.8x damage. If a 3 is rolled, this move deals 1.3x damage. Outside factors to damage are also affected by these multipliers.
A14: Discard | B14: 2 | C14: EoT | D14: 2 | E14: 3d10+2 | F14: Magical | G14: Standard | H14: 1 | I14: Foe | J14: Range 5 | K14: Roll a d20, on 15+ store a reroll that can be used to reroll any cards effect as a Once/Trigger action.
A15: Roulette | B15: 3 | C15: EoT | D15: 3 | E15: 3d8+5 | F15: Magical | G15: Standard | H15: 1 | I15: Foe | J15: Range 4 | K15: Roll a 1d8 to inflict a random status on the opponent, then roll a d3. If the d3 roll is 1, status the user instead. Statuses: 1 = 10 Bleed/1, 2 = 10 Poison/1, 3 = 10 Burn/1, 4 = 6 Cripple/1, 5 = Root/1, 6 = Seal/1, 7 = Stun/1, 8 = Confusion/1.
A16: Gamble | B16: 4 | C16: Twice/EoT | D16: 3 | E16: 3d8+3 | F16: Magical | G16: Standard | H16: 1 | I16: Foe | J16: Range 3 | K16: Roll d7. 1 = subtract the target's ATK and MAG. 2 = subtract the higher of the target's offensive stats. 3 = subtract the user's ATK. 4 = add the user's ATK. 5 = add the target's higher offense stat. 6 = add the user's MAG again. 7 = add the user's ATK and the target's ATK and MAG. This attack still adds the user's MAG and ignores 10 DEF.
A17: Double or Nothing | B17: 4 | C17: Twice/EoT | D17: - | E17: - | F17: - | G17: Trigger | H17: 1 | I17: Any | J17: Range 4 | K17: The user rolls a d2. On a 1, the target can't use Swift/Free actions until the end of the user's next turn. On a 2, the target gains an extra Swift action (or multiple Free actions) until the start of the user's next turn. If used on Self, this must be used at the start of the user's turn.
A18: Blackjack | B18: 5 | C18: Twice/EoT | D18: 3 | E18: 3d8+5 | F18: Magical | G18: Standard | H18: 1 | I18: Foe | J18: Range 3 | K18: On a successful hit, roll 2d10, treating 1s as either 1 or 11 (user’s choice). The user may choose to roll additional 1d10s to add to the roll. If the total is 17-20, this attack gains 1 base dice. On a total of 21, this attack instead gains 3 base dice and activates Jackpot. On a total of 22 or higher, the attack instead loses 2 base dice.
A19: Craps | B19: 6 | C19: Twice/E3T | D19: 5 | E19: 5d10-10 | F19: Magical | G19: Standard | H19: 1 | I19: Foe | J19: Range 3 | K19: This attack has Bomb dice. For every Bomb dice that triggers, the user may pick another foe within the target's Splash 1 to target (the same foe cannot be picked more than once). If 5+ bomb dice is triggered, this attack activates Jackpot. This attack is immune to (non-Cards) positive damage factors. On a critical hit, the extra dice from the critical hit do NOT have Bomb dice.
A20: Jackpot | B20: 7 | C20: Passive | D20: - | E20: - | F20: - | G20: - | H20: - | I20: - | J20: - | K20: When the user rolls the maximum roll on all dice in an accuracy, damage, or effect roll, for a total of at least 8, they gain +7 ATK/MAG, +7 DEF, +1 EVA, +1 ACC, and +2 MP for one round. This does not activate on Hi-Lo rolls, but instead activates when Hi-Lo reaches maximum dice. Repeated activation does not stack, but instead refreshes the duration.
A21: Slots Spin | B21: 8 | C21: Once | D21: 4 | E21: 5d8+0 | F21: Magical | G21: Standard | H21: 1 | I21: Foe | J21: Range 4 | K21: Roll 3d4. For every 4 rolled, this attack gains +1 dice. If no 4s are rolled, this attack gains -1 dice. if all dice are 4s, this attack gains an additional +1 dice.
A22: Hi-Lo | B22: 9 | C22: Twice/EoT | D22: 4 | E22: Xd10+5 | F22: Magical | G22: Standard | H22: 1 | I22: Foe | J22: Range 3 | K22: Roll a d10. The user predicts whether the next d10 result will be higher or lower than the previous result, then rolls again. On a correct guess, this attack gains +2 base dice and the user may continue predicting and rolling (max 5 guesses) or choose to stop. On a failed guess, the user stops and the attack loses half of its total base dice. If the roll is the same as the previous, reroll that dice.
A23: Stacked Deck | B23: 10 | C23: Once | D23: - | E23: 6d8+0 | F23: Magical | G23: Standard | H23: 1 | I23: Foe | J23: Melee | K23: In place of an accuracy roll, roll a 1d14 for an effect. 1. The opponent is healed by the roll, 2. The user takes 2x damage from all sources for one round, 3. The attack misses, 4. After damage, the user and target swap their current HP (can overheal, foes with over 200 HP are considered to have 200 HP for this effect), 5. For one round, attacks automatically hit the user, 6. The user and target gain a random position change, 7. The user and target are both Stunned/1, 8. 50% of this attack's damage is dealt to a random foe instead, 9. For one round, the user's attacks automatically hit, 10. The user gains a 1/Any/Global Once/Reaction: "Reroll one accuracy roll.", 11. Cleanse all statuses and numerical debuffs from the user & reset their other moves' frequencies, 12. Target is Sealed/1, 13. Next turn, the user may choose numbers for their cards effects, rather than rolling dice for them, 14. This attack has unremovable thrice base dice.
A24: Card Counter | B24: EX1 | C24: Every Turn | D24: - | E24: - | F24: - | G24: Reaction | H24: - | I24: Self | J24: - | K24: Once per turn, the user may choose to reroll their Cards dice effect (for Craps, reroll the damage dice).
A25: High Roller | B25: EX2 | C25: Every Turn | D25: - | E25: - | F25: - | G25: Trigger | H25: - | I25: Self | J25: - | K25: The user may choose to roll a 1d5 for each standard action the user has remaining this turn. The standard actions targeting amount becomes equal to the roll-1 (If a one is rolled, the standard is lost).
A26: Lunar Rod (Elissem)
A27: =Stats!H11 & " HP | " & Stats!I11 & " ATK | " & Stats!J11 & " MAG | " & Stats!K11 & " PDEF | " & Stats!L11 & " MDEF | " & Stats!M11 & " EVA | " & Stats!N11 & " MP " -> 70 HP | 3 ATK | 15 MAG | 0 PDEF | 3 MDEF | 0.7 EVA | 2 MP | G27: "Count the phases and strike when the Moon shines the brightest."
A28: Lunar Phase | B28: 1 | C28: Passive | D28: - | E28: - | F28: - | G28: - | H28: - | I28: Self | J28: - | K28: At the start of their first turn, the user picks a Phase. At the start of each following turn, the user shifts Phases in the following order. This Passive cannot be disabled. New Moon (+1 range) --> Waxing (+2 dice faces on accuracy and attacks) --> Full Moon (-1 dice on attacks targeting the user) --> Waning (+1 dice on attacks) --> New Moon, etc.
A29: Moonblast | B29: 1 | C29: Every Turn | D29: 3 | E29: 2d8+5 | F29: Magical | G29: Standard | H29: 1 | I29: Foe | J29: Range 3 | K29: The user's next Phase effect's value is increased by 1.
A30: Dark Reflection | B30: 2 | C30: EoT | D30: 4 | E30: 2d8+9 | F30: Magical | G30: Standard | H30: 1 | I30: Foe | J30: Range 4 | K30: For one round, the target is inflicted with the inverse effect of the user's Phase.
A31: Holy Light | B31: 3 | C31: EoT | D31: 3 | E31: 1d8+7 | F31: Magical | G31: Standard | H31: 1 | I31: Foe | J31: Range 6 | K31: If the user has Moonblast's or Celestial Blessing's effect, the target's status effects (except Seal and Stun) are extended by +1 round.
A32: Lunar Shift | B32: 4 | C32: E3T | D32: - | E32: - | F32: - | G32: Free | H32: 1 | I32: Self | J32: - | K32: The user shifts to their next Lunar Phase. If Moonblast's effect is active, it is transferred to the new Phase.
A33: Harvest Moon | B33: 5 | C33: Twice/EoT | D33: 3 | E33: 2d10+6 | F33: Magical | G33: Standard | H33: 1 | I33: Foe | J33: Range 4 | K33: If the user is in New Moon or Full Moon, they heal 1d10+2 HP. Otherwise, they do not shift Phases on their next turn. This may be used as a non-attack Standard.
A34: Tidal Wave | B34: 6 | C34: EoT | D34: 4 | E34: 3d8+7 | F34: Magical | G34: Standard | H34: AoE | I34: Foes | J34: Burst 1 | K34: Targets are inflicted with Confusion/1. New Moon grants +AoE range on this attack.
A35: Double Tide | B35: 7 | C35: Twice | D35: 4 | E35: 2d6+2 (Double Hit) | F35: Magical | G35: Standard | H35: 1 | I35: Foe | J35: Range 4 | K35: This attack Critical Hits on 16+. If this attack Critical Hits at least once, the user gains Moonblast's effect.
A36: Blood Moon | B36: 8 | C36: EoT | D36: 4 | E36: 2d8+6 | F36: Magical | G36: Standard | H36: 2 | I36: Foes | J36: Range 3 | K36: If the user is in Waxing or Waning, targets are inflicted with 2d6 Poison/1. Otherwise, targets are inflicted with 3d4 Bleed/1.
A37: Celestial Blessing | B37: 9 | C37: Twice/EoT | D37: - | E37: - | F37: - | G37: Free | H37: AoE | I37: Self and Allies | J37: Burst 1 | K37: Until the start of the user's next turn, targets gain the user's next Phase effect. Next turn, the user's Phase effect is disabled.
A38: Gravity Crash | B38: 10 | C38: Once | D38: 5 | E38: 2d10+9 | F38: Magical | G38: Standard | H38: 1 | I38: Foe | J38: Melee | K38: This attack has a different effect based on the user's Phase. New Moon: Homing 4. For one round, the target cannot use moves with Usage Limits. Waxing: Push 1d6. The target is inflicted with 4 Cripple/2. Full Moon: For one round, foes' abilities only deal 75% damage to allies in Range 5. Waning: This attack has Bomb dice.
A39: Far Side of the Moon | B39: EX1 | C39: Passive | D39: - | E39: - | F39: - | G39: - | H39: - | I39: Self | J39: - | K39: The user picks another Lunar Phase effect that doesn't shift in any way. This effect is active when their original Phase is not affected by Moonblast or Celestial Blessing. Lunar Rod attacks may use this Phase for effects instead of the original Phase.
A40: Fatal Moonlight | B40: EX2 | C40: Once | D40: 5 | E40: 2d10+10 | F40: Magical | G40: Standard | H40: 2 | I40: Foes | J40: Range 3 | K40: This attack has two effects if the user has two different Phases. New Moon: One target at max range is inflicted with Seal/1. Waxing: The user permanently gains +2d6 DEF. Full Moon: This attack may target +2 foes. Waning: This attack ignores negative damage factors.
A41: Orb (Taistelu)
...

Sheet Dark
A1: Name | B1: Lv. | C1: Frequency | D1: MR | E1: Damage | H1: Target | K1: Effect
E2: Roll | F2: Type | G2: Action | H2: Amount | I2: Group | J2: Range
A3: Basic Abilities
A4: =Classes!A4 -> Basic Attack | B4: =Classes!B4 -> B | C4: =Classes!C4 -> Every Turn | D4: =Classes!D4 -> 2 | E4: =Classes!E4 -> 1d10+2 | F4: =Classes!F4 -> Physical or Magical | G4: =Classes!G4 -> Standard | H4: =Classes!H4 -> 1 | ... K4: =Classes!K4 -> This attack is either Physical or Magical. Add ATK/MAG to the damage roll and subtract the target's PD/MD. This move's use cannot be prevented by any means, including Seal.
A5: =Classes!A5 -> Basic Movement | B5: =Classes!B5 -> B | C5: =Classes!C5 -> Every Turn | D5: =Classes!D5 -> - | E5: =Classes!E5 -> - | F5: =Classes!F5 -> - | G5: =Classes!G5 -> Movement | H5: =Classes!H5 -> - | ... K5: =Classes!K5 -> The user spends MP to move an equal amount of tiles. (For all purposes, Basic Movement is not an ability, but is still an action.)
A6: =Classes!A6 -> Dash | B6: =Classes!B6 -> B | C6: =Classes!C6 -> Every Turn | D6: =Classes!D6 -> - | E6: =Classes!E6 -> - | F6: =Classes!F6 -> - | G6: =Classes!G6 -> Full | H6: =Classes!H6 -> - | ... K6: =Classes!K6 -> The user spends MP to move up to x1.5 that amount of tiles (rounded down).
A7: =Classes!A7 -> Backstep | B7: =Classes!B7 -> B | C7: =Classes!C7 -> Passive | D7: =Classes!D7 -> - | E7: =Classes!E7 -> - | F7: =Classes!F7 -> - | G7: =Classes!G7 -> - | H7: =Classes!H7 -> - | ... K7: =Classes!K7 -> During the user's Movement/Full action, the user has unremovable -2 MP for the rest of the turn after leaving a foe's Melee.
A8: =Classes!A8 -> Attack of Opportunity | B8: =Classes!B8 -> B | C8: =Classes!C8 -> Every Turn | D8: =Classes!D8 -> 2 | E8: =Classes!E8 -> 1d10+2 | F8: =Classes!F8 -> Physical or Magical | G8: =Classes!G8 -> Reaction | H8: =Classes!H8 -> 1 | ... K8: =Classes!K8 -> This may be used on a foe in the user's Melee that either: 1. uses a ranged attack that doesn't target the user (after damage is rolled) or 2. leaves the user's Melee using Dash. (AoO still adds ATK/MAG and DEF.)
A9: Dark Abilities
A11: Athame (Ocean)
A12: =Stats!O9 & " HP | " & Stats!P9 & " ATK | " & Stats!Q9 & " MAG | " & Stats!R9 & " PDEF | " & Stats!S9 & " MDEF | " & Stats!T9 & " EVA | " & Stats!U9 & " MP " -> 65 HP | 9 ATK | 12 MAG | 5 PDEF | 2 MDEF | 1 EVA | 3 MP | G12: "Sacrifice your life force to boost your power without limit."
A13: Crimson Pact | B13: 1 | C13: Passive | D13: - | E13: - | F13: - | G13: - | H13: - | I13: - | J13: - | K13: Whenever the user damages a foe, they sacrifice HP equal to 10% of the total damage the foe took, if able. Then, they gain permanent bonus damage equal to the HP sacrificed. (Bonus damage is also gained through effect-derived CP.)
A14: Bloodrush | B14: 1 | C14: Every Turn | D14: 2 | E14: 2d8+4 | F14: Magical | G14: Standard | H14: 1 | I14: Foe | J14: Range 4 | K14: If this move is used from maximum range, the user gains +5 DMG and +1 MP/1.
A15: Defile | B15: 2 | C15: EoT | D15: 4 | E15: 1d10+5 | F15: Magical | G15: Standard | H15: AoE | I15: Foes | J15: Pierce 4 | K15: Targets are inflicted with 3 Curse/1. Whenever a foe takes damage from this Curse, the user takes an equal amount in Crimson Pact.
A16: Purloin Youth | B16: 3 | C16: E3T | D16: 3 | E16: 3d6+5 | F16: Magical | G16: Standard | H16: 1 | I16: Foe | J16: Melee | K16: For one round, attacks targeting the user have 10% recoil. The user sacrifices HP to Crimson Pact equal to half the recoil.
A17: Sanctified Blade | B17: 4 | C17: Once | D17: - | E17: - | F17: - | G17: Swift | H17: 1 | I17: Self | J17: - | K17: Crimson Pact's sacrifice amount on the user's next single-target attack is increased by 10%. If the Foe has targeted the user since the beginning of their last turn, the amount is increased by an additional 5%.
A18: Pentagram | B18: 5 | C18: E3T | D18: 4 | E18: 2d6+3 | F18: Magical | G18: Standard | H18: AoE | I18: Foes | J18: Burst 1 | K18: At the start of the user's next turn, foes in the user's Burst 1 take 2d6+3 plus the user's Crimson Pact in damage.
A19: Black Magic | B19: 6 | C19: Passive | D19: - | E19: - | F19: - | G19: - | H19: - | I19: - | J19: - | K19: For every 5 CP the user has, they have +1 DEF. For every 7 CP, they have +1 ACC. For every 10 CP, they have +1 damage dice.
A20: Massacre | B20: 7 | C20: Once | D20: 3 | E20: 2d8+11 | F20: Magical | G20: Standard | H20: 1 | I20: Foe | J20: Melee | K20: If this kills the target, the user gains twice the amount of Crimson Pact from it and an additional use of Massacre. Otherwise, this move does not trigger Crimson Pact sacrifice.
A21: Covenant | B21: 7 | C21: Once | D21: - | E21: - | F21: - | G21: Free | H21: 1 | I21: Ally | J21: Range 3 | K21: For one round, the target shares the user's Black Magic buffs and gains the Crimson Pact passive. Crimson Pact gained by the target is applied to the user instead.
A22: Exsanguinate | B22: 8 | C22: Once | D22: 4 | E22: 2d8+6 | F22: Magical | G22: Standard | H22: 1 | I22: Foe | J22: Melee | K22: If the user acquires a Black Magic bonus from the Crimson Pact gained from this move, the bonus gained is increased by 1.
A23: Siphon Soul | B23: 9 | C23: Twice/EoT | D23: 4 | E23: 3d8+2 | F23: Magical | G23: Standard | H23: 1 | I23: Foe | J23: Range 3 | K23: Before accuracy, the user heals HP equal to their Crimson Pact.
A24: Oblation | B24: 10 | C24: Once | D24: - | E24: - | F24: - | G24: Swift | H24: - | I24: Self | J24: - | K24: The user's next attack this turn gets double bonus damage from Crimson Pact.
A25: Total Depravity | B25: EX1 | C25: Passive | D25: - | E25: - | F25: - | G25: - | H25: - | I25: - | J25: - | K25: The user's Crimson Pact sacrifice is increased by 5%. At the start of each turn, if the user attacked on their last turn, they take damage equal to their Crimson Pact. This cannot kill the user.
A26: Bloodbind | B26: EX2 | C26: Every Turn | D26: - | E26: - | F26: - | G26: Trigger | H26: - | I26: - | J26: - | K26: This may be used up to twice per turn before the user attacks. The user sacrifices any amount of CP. For each point sacrificed, they gain +1 DMG this turn and heal 1 HP when using Standard/Full attacks, regardless of hit.
A27: Scythe (Ocean)
A28: =Stats!O11 & " HP | " & Stats!P11 & " ATK | " & Stats!Q11 & " MAG | " & Stats!R11 & " PDEF | " & Stats!S11 & " MDEF | " & Stats!T11 & " EVA | " & Stats!U11 & " MP " -> 55 HP | 9 ATK | 16 MAG | 6 PDEF | 4 MDEF | 0.6 EVA | 2 MP | G28: "Steals the opponent's HP with every attack."
A29: Reaper's Touch | B29: 1 | C29: Passive | D29: - | E29: - | F29: - | G29: - | H29: - | I29: - | J29: - | K29: Whenever the user damages a foe, the user heals 1/8 of the damage dealt.
A30: Reap | B30: 1 | C30: Every Turn | D30: 2 | E30: 2d8+3 | F30: Magical | G30: Standard | H30: 1 | I30: Foe | J30: Melee | K30: Reaper's Touch heals 1/5 of the damage dealt on this attack instead of 1/8.
A31: Hades' Toll | B31: 2 | C31: EoT | D31: 3 | E31: 2d10+1 | F31: Magical | G31: Standard | H31: 1 | I31: Foe | J31: Homing 4 | K31: For two rounds, the user's Reaper's Touch heal is increased 50% on attacks against the target.
A32: Haunted Swing | B32: 3 | C32: EoT | D32: 4 | E32: 3d6+4 | F32: Magical | G32: Standard | H32: AoE | I32: Foes | J32: Beam 2 | K32: Targets at full HP take an additional 5 damage. The user heals 5 HP for each target this triggers on.
A33: Wither Soul | B33: 4 | C33: EoT | D33: 3 | E33: 2d8+6 | F33: Magical | G33: Standard | H33: AoE | I33: Foes | J33: Burst 1 | K33: For each debuff or status that any target is under, the user heals an additional 3 HP from Reaper's Touch.
A34: Pestilent Strike | B34: 5 | C34: EoT | D34: 3 | E34: 2d10+8 | F34: Magical | G34: Standard | H34: 1 | I34: Foe | J34: Range 3 | K34: The target is inflicted with Poison/1 equal to the amount of Reaper's Touch healing calculated from this attack. If this amount is at least 6, the poison damage is halved and extended one round.
A35: Coup de Grâce | B35: 6 | C35: E3T | D35: 3 | E35: 2d8+5 | F35: Magical | G35: Standard | H35: 1 | I35: Foe | J35: Homing 5 | K35: If this kills a target, the user heals 10 HP and gains +5 damage to their next attack.
A36: Spirit Break | B36: 7 | C36: Twice | D36: 4 | E36: 5d6+5 | F36: Magical | G36: Standard | H36: 1 | I36: Foe | J36: Range 3 | K36: The target is inflicted with -3 DEF/1, and the user gains +3 DMG/1.
A37: Memento Mori | B37: 8 | C37: Twice/EoT | D37: 4 | E37: 4d8+5 | F37: Magical | G37: Standard | H37: 1 | I37: Foe | J37: Range 5 | K37: This attack's damage is delayed for one turn. The user may choose to delay it for up to 2 additional turns. For each additional turn delayed, the user heals an additional 1/8 of the damage from Reaper's Touch.
A38: Phantasmal Shield | B38: 8 | C38: Once | D38: - | E38: - | F38: - | G38: Swift | H38: 1 | I38: Self or Ally | J38: Melee | K38: For one round, the target heals 15% of the damage taken from all attacks. Each time the target is hit by a Standard/Full attack with this effect, it is decreased by 5% (minimum 0%).
A39: Stroke of Midnight | B39: 9 | C39: Twice/E3T | D39: 4 | E39: 2d6+12 | F39: Magical | G39: Standard | H39: 1 | I39: Foe | J39: Range 3 | K39: Before damage, for one round, the user's Reaper Touch healing is instead converted into additional damage on that attack. Other Scythe-sourced healing is converted into +DMG/1.
A40: Phantom Blade | B40: 10 | C40: Once | D40: 4 | E40: 6d6+6 | F40: Magical | G40: Standard | H40: 1 | I40: Foe | J40: Melee | K40: The amount the user heals from Reaper's Touch on this attack is equal to amount of HP the user has healed from Scythe abilities (except Phantom Blade) in the last round.
A41: Immortal Coil | B41: EX1 | C41: Passive | D41: - | E41: - | F41: - | G41: - | H41: - | I41: - | J41: - | K41: When the user would die for the first time, they are instead set to 1 HP and immediately take their turn. The user cannot take damage during this bonus turn. Then, they take damage equal to the overkill amount of the attack that would have killed them. Turn order then resumes normally.
...

Sheet Dueler
A1: Name | B1: Lv. | C1: Frequency | D1: MR | E1: Damage | H1: Target | K1: Effect
E2: Roll | F2: Type | G2: Action | H2: Amount | I2: Group | J2: Range
A3: Basic Abilities
A4: =Classes!A4 -> Basic Attack | B4: =Classes!B4 -> B | C4: =Classes!C4 -> Every Turn | D4: =Classes!D4 -> 2 | E4: =Classes!E4 -> 1d10+2 | F4: =Classes!F4 -> Physical or Magical | G4: =Classes!G4 -> Standard | H4: =Classes!H4 -> 1 | ... K4: =Classes!K4 -> This attack is either Physical or Magical. Add ATK/MAG to the damage roll and subtract the target's PD/MD. This move's use cannot be prevented by any means, including Seal.
A5: =Classes!A5 -> Basic Movement | B5: =Classes!B5 -> B | C5: =Classes!C5 -> Every Turn | D5: =Classes!D5 -> - | E5: =Classes!E5 -> - | F5: =Classes!F5 -> - | G5: =Classes!G5 -> Movement | H5: =Classes!H5 -> - | ... K5: =Classes!K5 -> The user spends MP to move an equal amount of tiles. (For all purposes, Basic Movement is not an ability, but is still an action.)
A6: =Classes!A6 -> Dash | B6: =Classes!B6 -> B | C6: =Classes!C6 -> Every Turn | D6: =Classes!D6 -> - | E6: =Classes!E6 -> - | F6: =Classes!F6 -> - | G6: =Classes!G6 -> Full | H6: =Classes!H6 -> - | ... K6: =Classes!K6 -> The user spends MP to move up to x1.5 that amount of tiles (rounded down).
A7: =Classes!A7 -> Backstep | B7: =Classes!B7 -> B | C7: =Classes!C7 -> Passive | D7: =Classes!D7 -> - | E7: =Classes!E7 -> - | F7: =Classes!F7 -> - | G7: =Classes!G7 -> - | H7: =Classes!H7 -> - | ... K7: =Classes!K7 -> During the user's Movement/Full action, the user has unremovable -2 MP for the rest of the turn after leaving a foe's Melee.
A8: =Classes!A8 -> Attack of Opportunity | B8: =Classes!B8 -> B | C8: =Classes!C8 -> Every Turn | D8: =Classes!D8 -> 2 | E8: =Classes!E8 -> 1d10+2 | F8: =Classes!F8 -> Physical or Magical | G8: =Classes!G8 -> Reaction | H8: =Classes!H8 -> 1 | ... K8: =Classes!K8 -> This may be used on a foe in the user's Melee that either: 1. uses a ranged attack that doesn't target the user (after damage is rolled) or 2. leaves the user's Melee using Dash. (AoO still adds ATK/MAG and DEF.)
A9: Dueler Abilities
A11: Gladius (bro torterra)
A12: =Stats!V9 & " HP | " & Stats!W9 & " ATK | " & Stats!X9 & " MAG | " & Stats!Y9 & " PDEF | " & Stats!Z9 & " MDEF | " & Stats!AA9 & " EVA | " & Stats!AB9 & " MP " -> 70 HP | 16 ATK | 3 MAG | 5 PDEF | 1 MDEF | 0.5 EVA | 2 MP | G12: "Swap between three different weapons to respond to any situation!"
A13: Triumvirate | B13: 1 | C13: Passive | D13: - | E13: - | F13: - | G13: - | H13: - | I13: Self | J13: - | K13: The user may swap between the following subweapons, each with respective effects: - Gladius: +1 dice on the user's attacks, - Scutum: attacks from range against the user lose 5 damage, - Pilum: Melee attacks gain +3 range. As a Standard action, the user may swap to any subweapon. Swapping due to a move effect occurs regardless of hit or miss. The user starts the game in Gladius.
A14: Exercitus | B14: 1 | C14: Every Turn | D14: 3 | E14: 3d6+6 | F14: Physical | G14: Standard | H14: 1 | I14: Foe | J14: Melee | K14: If in Gladius, swap to Scutum. If in Scutum, this has Push 3 and swap to Pilum. If in Pilum, this inflicts 4 Cripple/1 and swap to Gladius.
A15: Disengage | B15: 2 | C15: EoT | D15: 4 | E15: 2d10+7 | F15: Physical | G15: Standard | H15: 1 | I15: Foe | J15: Melee | K15: If used in Gladius, this attack inflicts -2d6 DEF/1 and has Push 1. If used in Scutum, the user takes half damage from AoE attacks for one round and is pushed back one tile. The user switches to Pilum.
A16: Forward Jab | B16: 3 | C16: EoT | D16: 3 | E16: 1d12+10 | F16: Physical | G16: Standard | H16: 1 | I16: Foe | J16: Line 6 (Pull 3) | K16: The user must be in Pilum to use this move. This attack has +1 base dice and Pull 4 against targets over 4 tiles away. The user switches to either Gladius or Scutum.
A17: Breach | B17: 4 | C17: EoT | D17: 4 | E17: 2d8+8 | F17: Physical | G17: Standard | H17: 1 | I17: Foe | J17: Range 4 | K17: The user switches to either Gladius or Scutum. If Gladius, for one round, foes who enter the user's melee take 3d8 damage. If Scutum, for one round, the user and allies in Burst 2 cannot have their DEF ignored. The user must switch subweapons.
A18: Phalanx | B18: 5 | C18: Twice/EoT | D18: 3 | E18: 3d4+1 | F18: Physical | G18: Reaction | H18: 1 | I18: Foe | J18: Range 4 | K18: If in Scutum, this may be used on a foe hitting the user or an ally in the user's melee. If the target is in melee, this has +1 dice and the user swaps to Gladius. Else, swap to Pilum. This ignores outside factors, does not add ATK/MAG, and ignores half DEF.
A19: Shield Wall | B19: 6 | C19: Twice/EoT | D19: 4 | E19: 2d10+4 | F19: Physical | G19: Standard | H19: AoE | I19: Foes | J19: Cone 1 | K19: The user must be in either Gladius or Pilum to use this move. The user switches to Scutum and for one round, the flat modifier in base rolls on attacks targeting the user become negative. This may be used as a non-damaging Standard.
A20: Iberian Steel | B20: 7 | C20: EoT | D20: - | E20: - | F20: - | G20: Free | H20: - | I20: Self | J20: - | K20: Subweapons are "used" when the user uses a weapon attack or weapon standard in it. The user's next attack this turn in a subweapon with fewer uses than both others gains +1 dice. If it has 2+ fewer uses than both others, it also gains +2 ACC.
A21: Deus Vult | B21: 8 | C21: Once | D21: 4 | E21: 2d12+2 | F21: Physical | G21: Standard | H21: 1 | I21: Foe | J21: Melee | K21: If used in Scutum, before accuracy, for one round, the user cannot be affected by any status or debuff and has any such effect removed.
A22: Invigorate | B22: 9 | C22: EoT | D22: - | E22: - | F22: - | G22: Swift | H22: AoE | I22: Self and Allies | J22: Burst 2 | K22: This move grants a different bonus based on the user's subweapon. Gladius: +5 DMG/1. Scutum: 7 Shield/1. Pilum: +1 ACC and CR/1.
A23: Dual Wield | B23: 9 | C23: E3T | D23: - | E23: - | F23: - | G23: Swift | H23: - | I23: Self | J23: - | K23: This must be used before the user moves. The user's MP is halved and they choose an additional subweapon to wield until the start of their next turn. Only the user's original subweapon is considered for subweapon swapping.
A24: Weapon Crash | B24: 10 | C24: Once | D24: 5 | E24: 2d10+3 | F24: Physical | G24: Standard | H24: Varies | I24: Foe(s) | J24: Varies | K24: This move has a different range and effect depending on the user's subweapon(s). Gladius: 1/Foe/Melee, and this attack has +3 dice faces. Scutum: AoE/Foes/Cone 2, and for one round, attacks targeting the user are immune to positive outside factors to accuracy and damage. Pilum: AoE/Foes/Pierce 5, and has -3 MR. If Dual Wield is active, the user picks one range and one effect from the subweapons.
A25: Impede | B25: EX1 | C25: EoT | D25: 4 | E25: 4d8+0 | F25: Physical | G25: Standard | H25: AoE | I25: Foes | J25: Pierce 4 | K25: If in Pilum, steal targets' buffs and set their duration to one round. Switch to Scutum. If in Scutum, this becomes AoE/Foes/Beam 4. Switch to Gladius. If in Gladius, gain +1 MP/1 and lower other cooldowns by one round. Switch to Pilum.
A26: Hastiliarius | B26: EX2 | C26: Passive | D26: - | E26: - | F26: - | G26: - | H26: - | I26: - | J26: - | K26: Each subweapon gains additional passive bonuses: Gladius: +0.5X dice, Scutum: +X DEF, Pilum: +0.5X ACC X is equal to the amount of times the user has used their least used subweapon.
A27: Quarterstaff (Taistelu)
A28: =Stats!V11 & " HP | " & Stats!W11 & " ATK | " & Stats!X11 & " MAG | " & Stats!Y11 & " PDEF | " & Stats!Z11 & " MDEF | " & Stats!AA11 & " EVA | " & Stats!AB11 & " MP " -> 65 HP | 16 ATK | 0 MAG | 5 PDEF | 3 MDEF | 0.9 EVA | 2 MP | G28: "A weapon focused on counterplay and anti-bullshit."
A29: Thwack | B29: 1 | C29: Every Turn | D29: 2 | E29: 2d6+6 | F29: Physical | G29: Standard | H29: 1 | I29: Foe | J29: Melee | K29: No status or effect, except Stun, can prevent this move's use. This ability has +1 dice for every 5 ATK or MAG (whichever is higher) the target has above 20.
A30: Grave of Titans | B30: 2 | C30: E3T | D30: 4 | E30: 3d8+0 | F30: Physical | G30: Standard | H30: 1 | I30: Foe | J30: Range 3 | K30: This attack ignores DEF. For every 10 max HP (before multipliers) the target has above 120, this attack gains +3 DMG and -1 MR. If this attack's damage is reduced by foes, the user's next Standard/Full attack has +1 ACC/CR and damage dice.
A31: Inertial Shift | B31: 3 | C31: EoT | D31: 3 | E31: 2d10+6 | F31: Physical | G31: Standard | H31: 1 | I31: Foe | J31: Melee (Push 3) | K31: If, in the last round, a foe's ability moved or attempted to move the user, this ability has +2 dice and becomes Homing 8 (Pull 7).
A32: Pole Vault | B32: 4 | C32: Twice/EoT | D32: 6 | E32: 3d10+5 | F32: Physical | G32: Standard | H32: 1 | I32: Tile | J32: Range 3 (Splash 1) | K32: Select an unoccupied tile in range, ignoring range reduction. The user teleports to this tile (even on miss) and targets foes (including Ice/Stone) in its Splash. If no foes are targetted, this is not an attack.
A33: Adaptive | B33: 5 | C33: Passive | D33: - | E33: - | F33: - | G33: - | H33: - | I33: - | J33: - | K33: When the user misses a Standard/Full attack, any buffs that attack would benefit from are applied to the user's next Standard/Full attack, which also gains +2 ACC, 10% of the damage the missed attack would have dealt, and ignores 5 DEF.
A34: Fair Fight | B34: 5 | C34: Twice/E3T | D34: - | E34: - | F34: - | G34: Free | H34: 1 | I34: Self | J34: - | K34: The target of the user's next single-target attack is the Duel Partner for two rounds or until the user or target dies or the user damages another foe. The user deals and takes 30 less damage from all foes except their DP. If the DP has allies or is a monster, this value is reduced to 5.
A35: Hardwood Slam | B35: 6 | C35: Twice/EoT | D35: 3 | E35: 2d8+4 | F35: Physical | G35: Standard | H35: 1 | I35: Foe | J35: Melee | K35: The user chooses the status inflicted if its conditions are met. This attack also gains -2 MR (if Poison), +2 dice (if Confusion), or heals the user 5 HP (if Bleed). 5 Poison/2: If the user's accuracy modifier is negative or the target has increased EVA. Confusion/2: If the target's accuracy modifiers caused them to hit an attack or trigger an effect they otherwise would not have on the user or their allies. 6 Bleed/2: If the target has critical hit or had +dice on an attack on the user and allies.
A36: Exploit Feign | B36: 7 | C36: Twice/EoT | D36: 4 | E36: 1d10+3 (Double Hit) | F36: Physical | G36: Standard | H36: 1 | I36: Foe | J36: Melee | K36: Targets are inflicted with -4 DEF/1 or -4 DMG/1. If the user is debuffed by foes, they are cleansed before accuracy, this attack gains a hit, and the debuff inflicted is doubled.
A37: Stance Breaker | B37: 8 | C37: E3T | D37: 4 | E37: 4d8-2 | F37: Physical | G37: Standard | H37: 1 | I37: Foe | J37: Range 4 | K37: If, in the last round, the target gained more than 5 DEF, HP or Shield, this attack has advantage damage dice. The user gains 75% of the DEF, HP or Shield (whichever is highest) that the target recieved in this time as Shield/1.
A38: Defiance | B38: 9 | C38: EoT | D38: 2 | E38: 2d4+5 | F38: - | G38: Reaction | H38: 1 | I38: Foe | J38: Global | K38: This may be used on a foe that statuses the user or targets them outside Range 4. The user teleports to an unoccupied tile in their Melee (even on miss) and gains +2 ACC and +5 DMG to their next Standard/Full attack. This attack ignores outside damage factors.
A39: Calamitous Trance | B39: 10 | C39: Once | D39: 5 | E39: 4d6+3 | F39: Physical | G39: Standard | H39: 1 | I39: Foe | J39: Melee | K39: If the target dealt 50+ damage to the user in the last round, this attack gains +3 dice. If 75+, this attack also gains +4 dice faces. This attack has -1 MR per attack that hit the user since their last turn, inflicting Confusion/2 when MR<4.
A40: Paragon | B40: EX1 | C40: Passive | D40: - | E40: - | F40: - | G40: - | H40: - | I40: - | J40: - | K40: Adaptive's numerical bonuses are tripled. On the user's turns, they gain 5X Shield and their attacks gain +5X% damage, where X = the number of times they were targetted by foes' abilities since their last turn.
A41: Martial Mastery | B41: EX2 | C41: Twice/EoT | D41: - | E41: - | F41: - | G41: Movement | H41: - | I41: - | J41: - | K41: The user moves up to their MP+1, treating all tiles except the final as Normal. For the rest of the turn, the user's attacks ignore obstructions and DEF and invert foe's negative numerical outside damage factors.
...

Sheet Heavy
A1: Name | B1: Lv. | C1: Frequency | D1: MR | E1: Damage | H1: Target | K1: Effect
E2: Roll | F2: Type | G2: Action | H2: Amount | I2: Group | J2: Range
A3: Basic Abilities
A4: =Classes!A4 -> Basic Attack | B4: =Classes!B4 -> B | C4: =Classes!C4 -> Every Turn | D4: =Classes!D4 -> 2 | E4: =Classes!E4 -> 1d10+2 | F4: =Classes!F4 -> Physical or Magical | G4: =Classes!G4 -> Standard | H4: =Classes!H4 -> 1 | ... K4: =Classes!K4 -> This attack is either Physical or Magical. Add ATK/MAG to the damage roll and subtract the target's PD/MD. This move's use cannot be prevented by any means, including Seal.
A5: =Classes!A5 -> Basic Movement | B5: =Classes!B5 -> B | C5: =Classes!C5 -> Every Turn | D5: =Classes!D5 -> - | E5: =Classes!E5 -> - | F5: =Classes!F5 -> - | G5: =Classes!G5 -> Movement | H5: =Classes!H5 -> - | ... K5: =Classes!K5 -> The user spends MP to move an equal amount of tiles. (For all purposes, Basic Movement is not an ability, but is still an action.)
A6: =Classes!A6 -> Dash | B6: =Classes!B6 -> B | C6: =Classes!C6 -> Every Turn | D6: =Classes!D6 -> - | E6: =Classes!E6 -> - | F6: =Classes!F6 -> - | G6: =Classes!G6 -> Full | H6: =Classes!H6 -> - | ... K6: =Classes!K6 -> The user spends MP to move up to x1.5 that amount of tiles (rounded down).
A7: =Classes!A7 -> Backstep | B7: =Classes!B7 -> B | C7: =Classes!C7 -> Passive | D7: =Classes!D7 -> - | E7: =Classes!E7 -> - | F7: =Classes!F7 -> - | G7: =Classes!G7 -> - | H7: =Classes!H7 -> - | ... K7: =Classes!K7 -> During the user's Movement/Full action, the user has unremovable -2 MP for the rest of the turn after leaving a foe's Melee.
