Workbook

Sheet Updates
A1: Battle Dome 4 updates (Beta)
A3: Current Patch: | B3: Beta 4.2
B5: Upcoming Patch: | D5: NONE
B6: Release Date: | D6: -
A8: Patch number | B8: Release date | C8: Summary
A9: 4.0.02 | B9: 16/8/16 | C9: Basic skill nerfs to polearm and skirmisher.
A10: 4.0.03 | B10: 24/8/16 | C10: Many ability changes for just about every class/branch.
A11: 4.0.04 | B11: 42630 | C11: Nerfs to skills and adjustments to level requirements.
A12: 4.0.05 | B12: 42637 | C12: Nerfs / Buffs to skills, adjustment to transferring weapons/classes, clarifying moves, and a new game mode.
A13: 4.0.06 | B13: 42643 | C13: Rapier buff, adjustment to skills.
A14: 4.0.07 | B14: 8/10/16 | C14: Small buffs, MR changes and Claws nerf.
A15: 4.0.08 | B15: 15/10/16 | C15: Shortbow + Katana buff, new cycle bonus.
A16: 4.0.09 | B16: 22/10/16 | C16: Axe Rework, MR changes and some adjustments.
A17: 4.0.10 | B17: 29/10/16 | C17: Skill Adjustment and Mechanic Changes.
A18: 4.0.11 | B18: 05/11/16 | C18: Move adjustments + Stat changes
A19: 4.0.12 | B19: 12/11/16 | C19: Skill adjustments and important overhaul of patch notes
A20: =HYPERLINK("https://docs.google.com/document/d/1OmgOHDN7s3SCsoJlMlG9kzIdx8Z65RSWNFO3LQwyQ-4/edit","See the changelog for changes past 4.0.12!") -> See the changelog for changes past 4.0.12!

Sheet 4.0 Mechanic Reversions
A1: The following is a list of mechanic changes between 4.1 and 4.0. This will explain things from 4.0's perspective: - Critical Hits only double the dice, not the modifier (so a 2d8+15 attack becomes 4d8+15) - The Defense stat has been removed - AoO will only apply to ranged attacks (this includes ranged attacks used in melee) - The EoT restriction will function differently: the only restriction is that you may not use an EoT move on the turn after you have used another EoT move (eg, you can go Twice -> EoT -> Once, but not EoT -> Twice/EoT) - Stats are a combination of class and weapon stats, rather than just clas stats, allowing for greater diversity - Moves have changed, so they will have different rolls, effects, MRs, etc. than in 4.1.

Sheet 4.0.12
A1: 4.0.12
A2: Release Date: | B2: 42715
A4: General
B5: Statuses
C6: Burn now reduces accuracy by 2 as an added side effect. Bleed reduces the targets damage by 5 as an added side effect.
C7: NEW STATUS: Poison: May deal passive damage to the foe, reduces foes evasion by 2
B8: EXP
C9: Teams get +1 XP
A10: Class
B11: Pyrokinetic
C12: Inferno
D13: Requires 1 Fire Stack minimum to use and no longer adds MAG.
B14: Rifter
C15: Levels
D16: Time Dilation and Wormhole have swapped levels
A17: Weapon
B18: Hammer
C19: Crush
D20: 2d8+5 | E20: 1d8+10 extra damage if the opponent is pushed either into another player or a wall
C21: Gale Force
D22: 2d8+5 | E22: 1d8+10 extra damage if target used the same move as last turn
B23: Bo Staff
C24: Tornado
D25: Confuses for 2 turns on 16+
B26: Rapier
C27: New level 1 move - Precision
D28: Similarly to Berserk, Rapiers may choose to gain -5 damage and +2 accuracy or -10 damage and +4 accuracy on their attacks.
B29: Polearm
C30: Levels
D31: Power Swing and Leg Sweep swapped
B32: Orb
C33: Spirit Shackle
D34: Can only target a maximum of 3 players now.
B35: Katana
C36: Nihonto
D37: MR4 now + Once
C38: Slice
D39: 2d8+8
C40: Fallen Blade
B41: Tonfa | D41: -1 acc now
...

Sheet 4.0.11
A1: 4.0.10
A2: Release Date: | B2: 12/11/16
A4: General
B5: Statuses | D5: V IMPLEMENTED ON THURSDAY V
C6: Burn now reduces accuracy by 2 as an added side effect. Bleed reduces the targets damage by 5 as an added side effect.
C7: NEW STATUS: Poison: May deal passive damage to the foe, reduces foes evasion by 2
B8: EXP
C9: Teams get +1 XP
A10: Class
A14: Weapon
B15: Hammer
C16: Crush
D17: 2d8+5 | E17: 1d8+10 extra damage if the opponent is pushed either into another player or a wall
C18: Gale Force
D19: 2d8+5 | E19: 1d8+10 extra damage if target used the same move as last turn
B20: Bo Staff
C21: Tornado
D22: Confuses for 2 turns on 16+
B23: Rapier
C24: New level 1 move - Precision
D25: Similarly to Berserk, Rapiers may choose to gain -5 damage and +2 accuracy or -10 damage and +4 accuracy on their attacks.
B26: Polearm
C27: Levels
D28: Power Swing and Leg Sweep swapped
B29: Orb
C30: Spirit Shackle
D31: Can only target a maximum of 3 players now.
B32: Katana
C33: Nihonto
D34: MR4 now + Once
B35: Tonfa
C36: Leash
D37: MR4

Sheet 4.0.10
A1: 4.0.10
A2: Release Date: | B2: 42672
A3: Concerns? PM either Taistelu, MMM, Micro, Henka or Hirl, if they're not on, PM some other staff. No staff on? Use %mail. No Kyubs? Cry in isolation. No PS!? Fear for your life that the hacker has returned OR USE THE ABILITY SUGGESTION FORM IN THE ROOMINTRO SERIOUSLY WHY DOES NO ONE USE THAT?
A4: General
B5: PvE
D6: If there are multiple monsters in a battle, the party automatically moves first.
B7: Terrain
C8: Lava
D9: 20 HP damage for entering, ending your turn is 30 HP damage.
B10: Mechanics
C11: The Twice move EoT descision was reversed (lol it was a really weird one).
C13: Moves that can be used on allies can now be used on consenting players similar to Ally Switch.
A15: Weapon
B16: Polearm
C17: Stats
D18: -5 HP and -2 ATK
B20: Wand
C21: Stats
D22: +5 HP and +1 MAG
C23: Chroma
D24: Now 2d8+9
B26: Tonfa
C27: Stats
D28: +5 HP
B29: Spellbook
C30: Seal
D31: d8+6, Seal 10+ on accuracy roll
C32: Bounty of Death
D33: d10+8
C34: Magic Shot (S)
B35: Longbow | D35: Now Line 4
C36: Snipe
D37: No longer crits on 18+ or makes next attack an automatic hit upon critting
C38: Focused Fire
D39: Reworked To: 1d10+7 | Push 3 effect | Range 2 | MR3 | EoT
B40: Crossbow
C41: Rupture/Pierce
D42: Levels are now swapped
B43: Shortbow
C44: Windmill
...

Sheet 4.0.08
A1: 4.0.08
A2: Release Date: | B2: 42658 | C2: Micro is STILL a nerd.
A3: Concerns? PM either Taistelu, MMM, Micro or Henka, if they're not on, PM Moq or Pancake, if they're not on, PM some other staff. No staff on? Use %mail. No Kyubs? Cry in isolation. No PS!? Fear for your life that the hacker returned.
A4: General
B5: New EXP Cycle Bonus
D6: +1 XP/Kill
A8: Class
B9: Pyrokinetic
C10: Maximum of one stack gained per turn.
A12: Weapon
B13: Crossbow
C14: Pierce
D15: Ignores accuracy reduction as well now.
B16: Shortbow
C17: Kip Up
D18: 2d8+12, Range 2
C19: String Shot
D20: If targetting ally, no damage is dealt, 3d8+14
C21: Eagle Eye
D22: Crit +17, -1 evasion.
B23: Katana
C24: Slice
D25: Roll: 2d10+4 -> 2d10+6
C26: Ni Dageki
D27: Roll: 2d8+4 -> 2d8+6
C28: Siedo
D29: Roll: 2d8+6 -> 2d8+12
C30: Nihonto
D31: Roll: 3d8+8 -> 3d8+12
C32: Stats
D33: +1 ATK @ Level 2 | +1 MAG @ Level 2
D34: +1 MAG @ Level 5

Sheet 4.0.07
A1: 4.0.07
A2: Release Date: | B2: Now | C2: Micro is STILL a nerd.
A3: Concerns? PM either Taistelu, MMM or Micro...if they're not on, PM Moq or Pancake, if they're not on, PM some other stuff. No staff on? Use %mail. No Kyubs? Cry in isolation.
A4: Class
B5: Bard
C6: Motivation
D7: The user now always gets the Motivation boost.
C8: Crescendo
D9: Frequency: Extended -> Full
B10: Guardian
C11: Protector
D12: Now Once/Swift
B13: Skirmisher
C14: Outmaneuver
D15: Effect: Add the users highest evasion stat to your next accuracy -> Add +2 accuracy to your next attack(all accuracy for multi-hitting moves)
A16: Weapon
B17: Gladius
C18: Bone Sword
D19: Roll: 3d10+2 -> 2d10+8
B20: Tonfa
C21: Leash
D22: Roll: 3d6+10 -> 3d8+10
C23: Figure 8
D24: Level 2 -> 3
C25: Dazing Shot
D26: Level 3 -> 2
B27: Rapier
C28: Riposte
D29: MR: 4 -> 2
D30: Frequency: EoT -> Every Turn
B31: Claws
C32: Gouge
D33: MR: 3 -> 4
C34: Puncture
D35: Frequency: Twice -> Once
D36: Roll: 2d8+10 -> 2d8+3
D37: Effect: Additional 15 damage if bleeding -> Additional 10 damage if bleeding
C38: Bagh Naka
D39: Roll: 2d8+10 -> 3d8
B40: Hammer
...

Sheet 4.0.06
A1: 4.0.06
A2: Release Date: | B2: Released
A3: If you want to suggest a change, or disagree with a change on here, PM either Taistelu, MMM or Micro. If they are not around, PM Moq or Pancake. If they are not around, PM another staff. If no staff are on, mail someone, if Ice Kyubs is down, cry in isolation.
A4: General
C5: Game Modes
D6: 2v2v2 and 2v2v2v2 are now playable. Base reward for 2v2v2 is 7 EXP. Base reward for 2v2v2v2 is 9 EXP.
C7: Glossary
D8: This was released before .06 but w/e.
C9: Cone
D10: Reworked, check Cone Examples tab on tracker/glossary!
A12: Classes
B13: Bard
C14: Bard has 1 less MP.
C15: Crescendo
D16: Clarify that it lasts one turn.
C17: Rising Hope
D18: Now only affects the Bard and teammates in melee range of the Bard.
B19: Skirmisher
C20: Skirm has one extra MP.
C21: Quick Thinking
D22: Now only lets the Skirmisher move with half its normal MP rounded down.
A24: Weapon
B25: Shortbow
C26: Stats
D27: Now gains 1 extra ATK at level 4 and level 5
C28: Kip Up
D29: 1d6+10 -> 2d8+10
C30: String Shot
D31: 2d6+8 -> 3d8+12 | F31: Frequency: Twice -> Once
B32: Longbow
C33: Snipe
D34: Frequency: Twice -> Once | G34: Roll: 5d10+5 -> 6d8+10
C35: Marksman
D36: +1d10 at 7 to 8 range -> +1d10 at 8 range
C37: Crippling Shot
D38: Roll: 2d10+6 -> 1d10+6
B39: Gladius
C40: Berserk
D41: Frequency: Passive -> Free/Trigger
B42: Spellbook
...

Sheet 4.0.05
A1: 4.0.05
A2: Release Date: | B2: 24/09/16 (Sat) (Released) | C2: Realm of the minor changes.
A3: Weapon reworks are being worked on even if they're not in this patch! | H3: micro is a nerd
A4: If you would like to comment on the Patch Notes, PM either Taistelu, MMM, microwavable, Pancake or Moq (people who work on balancing specifically) or use the Ability Suggestion Form (idk who has access to that though).
A5: General
C6: Turn Order
D7: d20+MP -> d8+MP
C8: Switching class/branch
D9: Players can switch class/weapon without having to reach level 3.
C10: Backstep
D11: Clarify that Backstep cannot be diagonal.
A14: Class
B15: CyroKinesis
C16: MP: 2 -> 3
C17: Frozen Heart
D18: Now also makes the user immune to roots.
C19: Invoke:Ice
D20: If the opponent's accuracy roll is 16+, they lose one dice on their attack.
B21: Pyrokinetic
C22: Comet
D23: Clarify that Comet isn't affected by Invoke:Fire.
B24: Guardian
C25: Heart Shield
D26: For all cases in which Heart Shield activates, Heart Shield now gives +1 evasion instead of +2.
A27: Weapon
B28: Gladius
C29: Swipe
D30: Level 2 -> Level 3 | F30: 10 HP recoil -> 15 HP recoil
C31: Blunt Force
D32: Level 3 -> Level 2
C33: Bone Sword
D34: Critical hit range is 18+ 14+
B36: Longbow
C37: Longbow
D38: Renamed to Marksman | Additional effect: +1d10 damage dice if at 7-8 range
C39: Snipe
D40: Roll: 3d10+5 -> 5d10+5
B42: Wand
C43: Magic Shot (W)
D44: Miss Rate 1 -> 3
...

Sheet 4.0.04
A1: 4.0.04
A2: Release Date: | B2: 9/17/16
A4: General
C5: Turn Order
D6: Turn order will now be based by rolling 1d20 and then adding your movement to the roll.
C7: Host Guide
D8: For those who wish to take up hosting in BD4, there is now a hosting guide in the Home Page.
A10: Weapon
B11: Gladius
C12: Etruia
D13: 2d10+10 -> 2d10+2 | F13: Level 4 -> Level 5
C14: Bone Sword
D15: Level 5 -> Level 4
B16: Polearm
C17: Impulse Skewer
D18: 3d10+5 -> 3d10+2
D19: Now only the first hit gets your Attack bonus.
B20: Longbow
C21: Longbow
D22: Removed: Longbows can't Backstep.
B23: Spellbook
C24: Wall of Air
D25: Old effect removed. New effect: You can choose to make this wall a straight 5x1 wall or a ringed wall with 3 diameter around yourself. Ranged attacks that pass through the wall get -2 accuracy and deal 50% damage rounded down. The wall itself is a slow terrain (requiring two movement to move onto). This wall lasts 5 turns, ending at the spellbooks turn or until the spellbook who cast this dies. You can only have one Wall of Air on the field at a time.
B26: Wand
C27: Magic Shot (W)
D28: Removed: This attack always hits. | G28: Miss rate: 1
C29: Energize
D30: Level 2 -> Level 3 | F30: Now requires 20 HP to be sacrificed instead of 10
C31: Life Drain
D32: Level 3 -> Level 2
C33: Blizzard
D34: Level 4 -> Level 5
C35: Chroma
D36: Level 5 -> Level 4

Sheet 4.0.03
A1: 4.0.03
A2: Release Date: | B2: 42606
A4: Basic Skills
B5: Dash
C6: Fixed a typo that makes it sound like dash gives you an additional 150%
B7: Attacks of Opportunity
C8: Added AoO's as a Basic Skill
A9: Class Skills
B10: CryoKinesis
C11: General
D12: Changed the spelling of the class
C13: Invoke: Ice
D14: Moved down to level 2
B15: PyroKinetic
C16: Potential Energy
D17: PE no longer loses all of the stacks if you use a different attack or don't attack
C18: Comet
D19: Moved down to level 2
D20: New: Comet's damage can't be affected by any outside modifier and does not gain bonus magic damage
C21: Ignition
D22: Clarified that Ignite doesn't stack with itself
D23: Range Burst 2 -> Burst 1
B24: Skirmisher
C25: Runner Up
D26: Removed
C27: Quick Thinking
D28: Level 1 Skirmisher ability. Allows skirmishers to use their move action after their standard action. This is a passive ability.
C29: Evade
D30: Moved down to level 2
D31: Evasions: 1,1,2,2,2 -> 0,0,0,1,1
B32: Guardian
C33: Radiance
D34: Moved down to level 2
C35: Iron Defense
D36: Removed
C37: Protector
D38: Moved down to level 4
C39: Oath of Mercy
D40: Level 5 Guardian ability. As a Swift action the Guardian gains +10 Damage Resistance until the end of their next turn. This ability has a frequency of Once.
B41: Bard
...

Sheet 4.0.02
A1: 4.0.02
A2: Release Date: | B2: 42598
A4: Weapon Skills
B5: Heavy - Polearm
C6: Power Swing
D7: 3d10+15 -> 2d10+10
C8: Leg Sweep
D9: 3d10+10 -> 2d10+6
D10: Miss rate 5 -> 4
D11: Polearm is a brusier. Sporting some of the highest damaging stats and attacks, however no one needs a 3d10+15 at level 1.
A12: Class Skills
B13: Skirmisher
C14: Glide
D15: No longer makes backstep a free action
D16: While extra movement for free might be awesome, it gives the skirmisher almost too much fun avoiding attacks of opportunity, additionally glide only giving 2x Movement makes it more in line with other skills

Sheet Home Page
A1: a | B1: Past Version: 4.3 Home Page!
B3: Ability Resources
B4: 4.3 Monsters
B6: =HYPERLINK("https://docs.google.com/spreadsheets/d/1xUe-NUahqo_JugC5LH5svDv46GNFziCUu9ebYzCdD-o/edit","Items List") -> Items List
B8: Class Abilities
B9: Weapon Branches
B10: Archer | C10: Celestial | D10: Clairvoyant | E10: Dark | F10: Dueler | G10: Fighter | H10: Heavy | I10: Regal | J10: Sorcerer
B11: Other Resources
B12: =HYPERLINK("https://docs.google.com/document/d/1uQf6GU1UkaTNPJjXjIe0jaj30t0HbgGVgMoMT2CR6T4/edit?usp=sharing","How to Play") -> How to Play
B14: Host Guide
B16: =HYPERLINK("https://docs.google.com/document/d/136sFrYkoo8cmcQljwF72LC30ywWgwXecfEhQcigRMH0/edit","Changelog") -> Changelog
B18: Glossary
A19: This is a previous version of Battle Dome. Version 4.4 can be found here: https://docs.google.com/spreadsheets/d/1KP-a4mvTbhhul9mONBqrsuCRzc2UoqodNQMpdT_3Zzk

Sheet BETA
B2: BETA CHANGELOG
B3: To use beta content, users must ask for special permission to host (betaperms). Beta games are looted as normal. Changes found here are for feedback and playtesting purposes and are in no way final. To discuss feedback, feel free to use the #suggestion_discussion channel or its Beta thread on the Discord or use the main chatroom.
B4: Date of Addition | C4: Change | D4: Created By | E4: Approved By | F4: Last Edited
B5: 44818 | C5: Game Mod - Pokemon in the Dome | D5: Salient | E5: Salient | F5: 28/06/2023
B6: 44973 | C6: Trickster Branch (Coins, Cards, Dice)+New Tarot Cards+New Status: Ruin | D6: OHKOff | E6: Krytocon | F6: 44975
B7: 45076 | C7: PvE Rework | D7: Salient / Krytocon | E7: Krytocon | F7: 45076
B8: 45187 | C8: BD Game Mods | D8: mistlo | E8: Elissem | F8: 45187
B9: 45259 | C9: 1vE Beta | D9: Taistelu | E9: Taistelu | F9: no one uses this column
B10: 45421 | C10: Cryo Rework | D10: God evening | E10: God evening | F10: hi
B11: 45446 | C11: Solar Rod Rework (Salient) | D11: Salient | E11: Taistelu | F11: Baked
B12: 45446 | C12: Solar Rod Rework (4mat) | D12: 4mat | E12: God evening | F12: Beans
B13: 45457 | C13: Star Rod Rework (Saya amanogawa) | D13: Saya | E13: God evening | F13: Are
B14: 45525 | C14: Cycle Beta | D14: God evening, Taistelu, Tapler, Oases | E14: Baked Beans | F14: Epic
B15: 45537 | C15: Version 4.4 | D15: BD Staff | E15: BD Staff | F15: 45537
C17: Changes are cool, but curious as to what old Battle Dome looked like? Check out the previous version of Battle Dome - 4.2 - here! | F17: "If you know the enemy, and know yourself, you need not fear the result of a hundred battles. If you know yourself but not the enemy, for every victory gained you will suffer a defeat. If you know neither enemy nor yourself, you will succumb in every battle." -Sun Tzu, Art of War | G17: semeoz is a noob lol

Sheet Classes
A1: Name | B1: Lvl | C1: Frequency | D1: MR | E1: Damage | H1: Target | K1: Effect
E2: Roll | F2: Type | G2: Action Type | H2: Amount | I2: Group | J2: Range and Modifiers
A3: Basic Abilities
A4: Basic Attack (P) / Basic Attack (M) | B4: B | C4: Every Turn | D4: 2 | E4: 1d10+2 | F4: Physical or Magical | G4: Standard | H4: 1 | I4: Foe | J4: Melee | K4: A basic attack. The user may choose either BATK (P) or BATK (M). Add the corresponding stat depending on their choice (BATK (P) = Physical Attack. BATK (M) = Magical Attack).This attack can be used even when sealed and its use cannot be prevented by any means, outside of Stun.
A5: Dash | B5: B | C5: Every Turn | D5: - | E5: - | F5: - | G5: Full | H5: - | I5: Self | J5: - | K5: The user moves up to 1.5x their MP (rounded down) instead of 1x. (Dash is a Full action, which takes up both the Movement and Standard actions.)
A6: Backstep | B6: B | C6: Every Turn | D6: - | E6: - | F6: - | G6: Movement | H6: - | I6: Self | J6: - | K6: This can only be used while a foe is in the user's Melee. The user moves one tile in a cardinal direction without triggering Attack of Opportunity.
A7: Attack of Opportunity | B7: B | C7: Every Turn | D7: 2 | E7: 1d10+2 | F7: Physical or Magical | G7: Reaction | H7: 1 | I7: Foe | J7: Melee | K7: This may be used when a foe in the user's Melee either: leaves that Melee with their Movement action, or uses a ranged attack that doesn't target the user (after damage is rolled). This Reaction still adds ATK or MAG.
A8: Class Abilities
A10: Bard
A11: 80 HP | 6 ATK | 6 MAG | 22 PD | 22 MD | 3 MP | G11: "Support yourself and others with damage and accuracy bonuses."
A12: Rising Hope | B12: 1 | C12: Passive | D12: - | E12: - | F12: - | G12: Passive | H12: AoE | I12: Self and Allies | J12: Burst 1 | K12: The user and allies in Melee range have +1 Accuracy and +1 Crit Range. Allies that have received Harmony or a buff from the user since the start of their previous turn gain a bonus +1 ACC. The user also gains +1 ACC while this bonus is active. Rising Hope does not stack with more than one Bard.
A13: Harmony | B13: 3 | C13: Twice/E2T | D13: - | E13: - | F13: - | G13: Swift | H13: 1 | I13: Self or Ally | J13: Range 3 | K13: For one round, the target cannot be affected by any status or debuff and has any such effect removed. If the target is affected by unremovable Poison, Burn or Bleed upon the usage or during the duration of this move, they gain +2 EVAs, +2 ACC, or +5 DMG respectively for the duration of the status. This move does not interact with self-inflicted statuses or debuffs in any way.
A14: Encore | B14: 5 | C14: Every Turn | D14: - | E14: - | F14: - | G14: Standard or Reaction | H14: - | I14: Self | J14: - | K14: Roll 1d20 and store the result (max one stored roll). As a Reaction, before the user or an ally in Range 3 rolls an accuracy check of an attack, the stored roll is used instead.
A15: Primadonna | B15: 7 | C15: Once | D15: - | E15: - | F15: - | G15: Free | H15: 1 or 2 | I15: Self or Self and Ally | J15: Global | K15: Targets gain +5 ATK/MAG and -5 DR permanently. If either effect is cleansed, the other is removed. After one round, targets may choose to lose the buff as a Free action. This does not stack.
A16: Crescendo | B16: 10 | C16: Once | D16: - | E16: - | F16: - | G16: Swift | H16: AoE | I16: Self and Allies | J16: Star 5 | K16: All targets gain +7 DR and +1 EVA until the start of the user's next turn. If the user's Primadonna is active, they instead gain +1 ACC, +5 DMG, and +2 Crit Range. This ability may be used as a Standard action instead to have Global range, provide a 50% boost (rounded up) to the buff values, and increase their duration to one round.
A17: Cryokinetic
A18: 75 HP | 7 ATK | 7 MAG | 21 PD | 21 MD | 3 MP | G18: "Geared toward defense, with strong utility."
A19: Invoke: Ice | B19: 1 | C19: Passive | D19: - | E19: - | F19: - | G19: Passive | H19: - | I19: - | J19: - | K19: When targeted with a non- Free, Swift, or Global attack from a foe, the user gains an Ice Stack (max three) after the move is resolved. Only two Ice Stacks can be gained per round. If the accuracy roll of an attack targeting the user rolls X+, that attack loses one die, where X = 15 - # of Ice Stacks.
A20: Mist | B20: 3 | C20: Twice | D20: - | E20: - | F20: - | G20: Free | H20: - | I20: Self | J20: - | K20: For one round, all attacks made by enemies from inside the user's Burst 2 deal -5 damage. The user may spend up to two Ice Stacks to extend this effect's duration by one for each stack used, or spend three stacks for a duration of two rounds and a range of Burst 3. This move cannot be used again while its effect is active.
A21: Frost Barrier | B21: 5 | C21: Twice | D21: - | E21: 2d8+X | F21: - | G21: Swift | H21: - | I21: Self | J21: - | K21: The user gains a Shield/1 equal to 2d8+X, where X is thrice the amount of Ice Stacks the user chooses to spend, minimum one stack.
A22: Ice Wall | B22: 7 | C22: Once | D22: - | E22: - | F22: - | G22: Movement or Free | H22: - | I22: - | J22: Range 5 | K22: The user creates a 3-tile wall of Ice in a cardinal direction, or a diagonal one with halved length (rounded up). This Ice has 15 HP. Foes who end their turn with at least one of these Ice tiles in their melee take 10 damage. The user may spend Ice Stacks to increase the wall's base length by one for each stack spent. The wall expires after 3 rounds. The user may shatter the wall as a Trigger action after one turn, destroying it and inflicting 3 Bleed/2 on foes within melee of it. This move ignores Range Rule.
A23: Flash Freeze | B23: 10 | C23: Once | D23: - | E23: - | F23: - | G23: Reaction | H23: - | I23: - | J23: Global | K23: This player may use this when targeted by an attack after damage has been rolled, and must spend one Ice Stack to do so. The interrupted attack loses all of its additive dice (excluding Critical Hit). The user may spend an additional Ice Stack to also remove the attack's additive positive damage modifiers, or two additional Ice Stacks to remove all positive damage factors. This ability cannot remove advantage damage dice.
A24: Guardian
A25: 85 HP | 5 ATK | 5 MAG | 30 PD | 30 MD | 3 MP | G25: "Protect yourself and allies."
A26: Strike Guard | B26: 1 | C26: Passive | D26: - | E26: - | F26: - | G26: Passive | H26: - | I26: - | J26: - | K26: If the opponent rolls 14+ on their accuracy on an attack that is targetting the user or an ally in their Melee, the attack deals -5 damage.
A27: Vanguard | B27: 3 | C27: Twice/EoT | D27: - | E27: - | F27: - | G27: Reaction | H27: 1 | I27: Ally | J27: Homing 4 | K27: This move may be used when an ally in range is targeted by an attack, after damage is rolled. The user moves to a tile in the ally's melee, and the ally takes 5 less damage from the attack. If the user is also a target of the attack, both the user and the Ally take 10 less damage instead. This effect does not stack with multiple Guardians.
A28: Fortify | B28: 5 | C28: Once | D28: - | E28: - | F28: - | G28: Swift | H28: 1 | I28: Self or Ally | J28: Homing 4 | K28: The target gains X Shield/1, where X is 35% of the amount of damage the user has taken directly from attacks since the beginning of their last turn (max 30 Shield).
A29: Tenacity | B29: 7 | C29: Thrice | D29: - | E29: - | F29: - | G29: Trigger | H29: 1 | I29: Self or Ally | J29: Homing 4 | K29: If the target was alive and was not attacked last round, they heal 15% of their missing HP. This can only be used once per turn.
A30: Radiance | B30: 10 | C30: Once | D30: - | E30: - | F30: - | G30: Swift | H30: - | I30: Self | J30: - | K30: The user takes 80% damage from attacks for two rounds. Additionally, for one round, whenever an ally is targeted by an attack from within the user’s Burst 2, the user may use a Reaction to redirect 30% of the damage the ally would take to themselves. (Redirected damage cannot be reduced by any means, nor can it stack with multiple users.)
A31: Pyrokinetic
A32: 65 HP | 11 ATK | 11 MAG | 16 PD | 16 MD | 3 MP | G32: "Geared towards offense at a slower pace."
A33: Invoke: Fire | B33: 1 | C33: Passive | D33: - | E33: - | F33: - | G33: Passive | H33: - | I33: - | J33: - | K33: When targetting a foe with a non- Free, Swift, or Global attack, the user gains a Fire Stack (max three) after the move is resolved. After gaining a Fire Stack, the user cannot gain another one until the start of their next turn. If the accuracy roll of an attack by the user rolls X+, that attack gains one die, where X = 15 - # of Fire Stacks the user has.
A34: Ignition | B34: 3 | C34: EoT | D34: - | E34: - | F34: - | G34: Free | H34: - | I34: Self | J34: - | K34: The user spends 1 to 3 Fire Stacks to use this move. Their next attack gains 3X Burn/1, where X is the number of Stacks spent.
A35: Comet | B35: 5 | C35: Twice | D35: 2 | E35: 1d4+2 | F35: Magical | G35: Movement | H35: 2 | I35: Foes | J35: Melee | K35: The user does the following things in any order: deals damage equal to the rolled amount to up to two foes in melee range, moves up to their full MP range. This move is immune to outside damage factors. Do not add MAG.
A36: Afterburn | B36: 7 | C36: Once | D36: - | E36: - | F36: - | G36: Free | H36: - | I36: Self | J36: - | K36: The user gains +accuracy equal to X+1 for one turn, where X is the amount of Fire Stacks the user chooses to spend, minimum one stack.
A37: Kinetic Energy | B37: 10 | C37: Once | D37: - | E37: - | F37: - | G37: Free | H37: - | I37: Self | J37: - | K37: The user spends two Fire Stacks to gain +10 damage on their next attack, or three Fire Stacks to gain +2 dice and +15 damage to their next attack.
A38: Rifter
A39: 60 HP | 9 ATK | 9 MAG | 19 PD | 19 MD | 3 MP | G39: "Deal lots of damage in short bursts."
A40: Time Matrix | B40: 1 | C40: Passive | D40: - | E40: - | F40: - | G40: Passive | H40: AoE | I40: Self and Allies | J40: Burst 1 | K40: If the user or an ally in Burst 1 rolls 14+ for their accuracy on an attack, the attack deals +5 damage.
A41: Rewind | B41: 3 | C41: EoT | D41: - | E41: - | F41: - | G41: Reaction | H41: 1 | I41: Self or Ally | J41: Range 4 | K41: This move can be used after the target rolls damage for an attack. The target may reroll up to 3 damage dice, but the user takes 3% of the attack's damage per die rerolled as recoil. Rerolled dice cannot trigger bombs or inverse bombs.
...

Sheet Archer
A1: Name | B1: Lvl | C1: Frequency | D1: MR | E1: Damage | H1: Target | K1: Effect
E2: Roll | F2: Type | G2: Action Type | H2: Amount | I2: Group | J2: Range and Modifiers
A3: Basic Abilities
A4: =Classes!A4 -> Basic Attack (P) / Basic Attack (M) | B4: =Classes!B4 -> B | C4: =Classes!C4 -> Every Turn | D4: =Classes!D4 -> 2 | E4: =Classes!E4 -> 1d10+2 | F4: =Classes!F4 -> Physical or Magical | G4: =Classes!G4 -> Standard | H4: =Classes!H4 -> 1 | ... K4: =Classes!K4 -> A basic attack. The user may choose either BATK (P) or BATK (M). Add the corresponding stat depending on their choice (BATK (P) = Physical Attack. BATK (M) = Magical Attack).This attack can be used even when sealed and its use cannot be prevented by any means, outside of Stun.
A5: =Classes!A5 -> Dash | B5: =Classes!B5 -> B | C5: =Classes!C5 -> Every Turn | D5: =Classes!D5 -> - | E5: =Classes!E5 -> - | F5: =Classes!F5 -> - | G5: =Classes!G5 -> Full | H5: =Classes!H5 -> - | ... K5: =Classes!K5 -> The user moves up to 1.5x their MP (rounded down) instead of 1x. (Dash is a Full action, which takes up both the Movement and Standard actions.)
A6: =Classes!A6 -> Backstep | B6: =Classes!B6 -> B | C6: =Classes!C6 -> Every Turn | D6: =Classes!D6 -> - | E6: =Classes!E6 -> - | F6: =Classes!F6 -> - | G6: =Classes!G6 -> Movement | H6: =Classes!H6 -> - | ... K6: =Classes!K6 -> This can only be used while a foe is in the user's Melee. The user moves one tile in a cardinal direction without triggering Attack of Opportunity.
A7: =Classes!A7 -> Attack of Opportunity | B7: =Classes!B7 -> B | C7: =Classes!C7 -> Every Turn | D7: =Classes!D7 -> 2 | E7: =Classes!E7 -> 1d10+2 | F7: =Classes!F7 -> Physical or Magical | G7: =Classes!G7 -> Reaction | H7: =Classes!H7 -> 1 | ... K7: =Classes!K7 -> This may be used when a foe in the user's Melee either: leaves that Melee with their Movement action, or uses a ranged attack that doesn't target the user (after damage is rolled). This Reaction still adds ATK or MAG.
A8: Archer Abilities
A10: Crossbow
A11: 65 HP | 11 ATK | 7 MAG | 13 PD | 14 MD | 1 MP | G11: "A weapon that has increased damage and effects the more you target an opponent."
A12: Hunter's Mark | B12: 1 | C12: Passive | D12: - | E12: - | F12: - | G12: Passive | H12: - | I12: - | J12: - | K12: When the user's Crossbow attack resolves, targets of the attack gain 1 Mark each. The user's attacks deal +5% damage per Mark on one target (does not stack with multiple targets). Marks only apply to their user's attacks.
A13: Arrow Flurry | B13: 1 | C13: Every Turn | D13: 3 | E13: 2d8+7 | F13: Physical | G13: Standard | H13: 1 | I13: Foe | J13: Range 6 | K13: If the original target has a Mark, this move gains Splash 1. If the target has 2+ Marks, this move instead gains Splash 2.
A14: Arrow Net | B14: 2 | C14: E2T | D14: 4 | E14: 3d8+4 | F14: Physical | G14: Standard | H14: 1 | I14: Foe | J14: Range 6 | K14: If the target has a Mark, they are inflicted with Slow/1. If the target has 2+ Marks, the user may inflict the target with 6 Cripple/1 instead.
A15: Shadow Quiver | B15: 3 | C15: Once | D15: - | E15: - | F15: - | G15: Swift | H15: - | I15: Self | J15: - | K15: The user's next attack becomes Magical and ignores all obstructions in its path (including Air tiles and Personal Bubble).
A16: Scoping Shot | B16: 4 | C16: EoT | D16: 3 | E16: 2d10+6 | F16: Physical | G16: Standard | H16: 1 | I16: Foe | J16: Line 4 | K16: For one round, all attacks on the target gain +1 ACC for every mark the target has.
A17: Quick Scope | B17: 5 | C17: Twice/EoT | D17: 3 | E17: 1d8+2 | F17: Physical | G17: Swift | H17: 1 | I17: Foe | J17: Range 6 | K17: This attack is immune to outside damage factors. Do not add ATK/MAG.
A18: Explosive Shot | B18: 6 | C18: Once | D18: 4 | E18: 2d8+6 | F18: Physical | G18: Standard | H18: 1 | I18: Foe | J18: Range 6 | K18: The target gains a "bomb". The user may choose to detonate this bomb as a trigger action on their turn, dealing 1d8+2X Bomb damage to all foes within Burst 2 of the target, where X is the amount of Marks the target has. The bomb automatically detonates when the user or target dies, or after two rounds.
A19: Tornado Bolt | B19: 7 | C19: Twice/EoT | D19: 4 | E19: 2d8+5 | F19: Physical | G19: Standard | H19: 1 | I19: Foe | J19: Line 6 (Push X) | K19: This move has Push X, where X is the amount of Marks the target has. If the target is unable to be pushed the full distance, the target gains another Mark.
A20: Pierce | B20: 8 | C20: EoT | D20: 5 | E20: 2d10+8 | F20: Physical | G20: Standard | H20: AoE | I20: Foes | J20: Pierce 6 | K20: If a target has 1+ Marks, this move ignores evasions. If a target has 2+ marks, this move also ignores negative accuracy modifiers.
A21: Serrated Arrows | B21: 9 | C21: Twice/E2T | D21: 4 | E21: 4d8+1 | F21: Physical | G21: Standard | H21: 1 | I21: Foe | J21: Range 6 | K21: This move inflicts 5 Bleed/X, where X is the amount of Marks the target has.
A22: Ballista | B22: 10 | C22: Once | D22: 5 | E22: 3d8+5X | F22: Physical | G22: Standard | H22: 1 | I22: Foe | J22: Line 6 | K22: This may only be used on a target with 2+ Marks. The X in this attack is the amount of Marks the target has.
A23: Longbow
A24: 65 HP | 12 ATK | 2 MAG | 6 PD | 6 MD | 1 MP | G24: "A high range weapon that excels in beating defence and other 'bullshit'."
A25: Skill Shot | B25: 1 | C25: Every Turn | D25: 2 | E25: 2d8+5 | F25: Physical | G25: Standard | H25: 1 | I25: Foe | J25: Range 8 | K25: This move can be used regardless of the user’s statuses (except stun) or foes’ move effects, and it cannot be prevented from doing damage.
A26: Chase Arrow | B26: 2 | C26: EoT | D26: 3 | E26: 3d8+4 | F26: Physical | G26: Standard | H26: 1 | I26: Foe | J26: Homing 6 | K26: This attack is immune to outside damage factors.
A27: Rupture | B27: 3 | C27: EoT | D27: 5 | E27: 2d8+9 | F27: Physical | G27: Standard | H27: 1 | I27: Foe | J27: Range 8 | K27: This attack ignores Evasions and outside accuracy factors. If the target's Evasions are increased or this attack is affected by accuracy factors by an effect from a foe, the target is inflicted with Bleed 5/1.
A28: Long Shot | B28: 4 | C28: E2T | D28: 3 | E28: 3d6+7 | F28: Physical | G28: Standard | H28: 1 | I28: Foe | J28: Range 8 | K28: This attack's range cannot be reduced. If the target has targeted the user from outside Range 6 before, they are inflicted with Seal/1.
A29: Bow Slam | B29: 5 | C29: E2T | D29: 3 | E29: 4d8+2 | F29: Physical | G29: Standard | H29: AoE | I29: Foes | J29: Cone 1 (Push 3) | K29: Targets are pushed in the direction of the Cone. For two rounds, the user cannot be moved by foes and is immune to effects dependent on Push/Pull.
A30: Ricochet | B30: 6 | C30: Twice/E2T | D30: 4 | E30: 2d10+6 | F30: Physical | G30: Standard | H30: 1 | I30: Foe | J30: Range 6 | K30: If the target dealt a total of 55+ damage to the user since the beginning of the user's last turn, this attack gains +2 dice.
A31: Tranquil Technique | B31: 7 | C31: Twice/EoT | D31: 4 | E31: 1d8+14 | F31: Physical | G31: Standard | H31: 1 | I31: Foe | J31: Range 8 | K31: If the target used a Reaction move since the beginning of the user's last turn, the user gains +2 accuracy on this and their next attack.
A32: Squall Volley | B32: 8 | C32: Twice/EoT | D32: 5 | E32: 1d10+6 | F32: Physical | G32: Standard | H32: 1 | I32: Foe | J32: Range 6 (Double Hit) | K32: If the user is debuffed from effects originating from foes, this attack ignores those debuffs that the user has and hits thrice instead.
A33: Arrow Rain | B33: 9 | C33: Once | D33: 4 | E33: 3d10+5 | F33: Physical | G33: Standard | H33: 1 | I33: Foes | J33: Range 6 (Splash 1) | K33: Foes hit are inflicted with any status effects the user has. The user may choose to target an empty space instead of a player for -3 accuracy on this attack.
A34: Shatter Shot | B34: 10 | C34: Once | D34: 4 | E34: 3d10+8 | F34: Physical | G34: Standard | H34: 1 | I34: Foe | J34: Range 6 | K34: This attack inverts numerical negative outside factors to damage and dice that do not originate from the user.
A35: Shortbow
A36: 60 HP | 10 ATK | 5 MAG | 9 PD | 9 MD | 3 MP | G36: "A precise weapon with high accuracy and critical chance, but lower non-critical damage."
A37: Hawkeye | B37: 1 | C37: Every Turn | D37: - | E37: - | F37: - | G37: Trigger | H37: - | I37: Self | J37: - | K37: Up to twice per turn, the user may choose to sacrifice 5 damage for +2 accuracy and +2 crit range this turn. This debuff is unremovable.
A38: Blitz | B38: 1 | C38: Every Turn | D38: 3 | E38: 2d6+0 | F38: Physical | G38: Standard | H38: 1 | I38: Foe | J38: Range 4 (Double Hit) | K38: This attack critical hits on 18+. For each successful hit, the user gains +4 damage on their next attack.
A39: Windmill | B39: 2 | C39: EoT | D39: 3 | E39: 3d6+6 | F39: Physical | G39: Standard | H39: AoE | I39: Foes | J39: Burst 1 | K39: This attack has +2 ACC and +2 CR for every target.
A40: Venom Shot | B40: 3 | C40: Twice/EoT | D40: 3 | E40: 2d8+5 | F40: Physical | G40: Standard | H40: 1 | I40: Foe | J40: Range 4 | K40: This attacks inflicts X Poison/1 on the target, where X is 2* accuracy bonus the user has. (If the user has no accuracy bonus, do not inflict Poison.)
A41: Homing Shot | B41: 4 | C41: EoT | D41: - | E41: 1d8+9 | F41: Magical | G41: Standard | H41: 1 | I41: Foe | J41: Homing 4 | K41: This move automatically hits the target. (This move still rolls accuracy.)
...

Sheet Celestial
A1: Name | B1: Lvl | C1: Frequency | D1: MR | E1: Damage | H1: Target | K1: Effect
E2: Roll | F2: Type | G2: Action Type | H2: Amount | I2: Group | J2: Range and Modifiers
A3: Basic Abilities
A4: =Classes!A4 -> Basic Attack (P) / Basic Attack (M) | B4: =Classes!B4 -> B | C4: =Classes!C4 -> Every Turn | D4: =Classes!D4 -> 2 | E4: =Classes!E4 -> 1d10+2 | F4: =Classes!F4 -> Physical or Magical | G4: =Classes!G4 -> Standard | H4: =Classes!H4 -> 1 | ... K4: =Classes!K4 -> A basic attack. The user may choose either BATK (P) or BATK (M). Add the corresponding stat depending on their choice (BATK (P) = Physical Attack. BATK (M) = Magical Attack).This attack can be used even when sealed and its use cannot be prevented by any means, outside of Stun.
A5: =Classes!A5 -> Dash | B5: =Classes!B5 -> B | C5: =Classes!C5 -> Every Turn | D5: =Classes!D5 -> - | E5: =Classes!E5 -> - | F5: =Classes!F5 -> - | G5: =Classes!G5 -> Full | H5: =Classes!H5 -> - | ... K5: =Classes!K5 -> The user moves up to 1.5x their MP (rounded down) instead of 1x. (Dash is a Full action, which takes up both the Movement and Standard actions.)
A6: =Classes!A6 -> Backstep | B6: =Classes!B6 -> B | C6: =Classes!C6 -> Every Turn | D6: =Classes!D6 -> - | E6: =Classes!E6 -> - | F6: =Classes!F6 -> - | G6: =Classes!G6 -> Movement | H6: =Classes!H6 -> - | ... K6: =Classes!K6 -> This can only be used while a foe is in the user's Melee. The user moves one tile in a cardinal direction without triggering Attack of Opportunity.
A7: =Classes!A7 -> Attack of Opportunity | B7: =Classes!B7 -> B | C7: =Classes!C7 -> Every Turn | D7: =Classes!D7 -> 2 | E7: =Classes!E7 -> 1d10+2 | F7: =Classes!F7 -> Physical or Magical | G7: =Classes!G7 -> Reaction | H7: =Classes!H7 -> 1 | ... K7: =Classes!K7 -> This may be used when a foe in the user's Melee either: leaves that Melee with their Movement action, or uses a ranged attack that doesn't target the user (after damage is rolled). This Reaction still adds ATK or MAG.
A8: Celestial Abilities
A10: Lunar Rod
A11: 70 HP | 1 ATK | 13 MAG | 6 PD | 10 MD | 2 MP | G11: "Shift phases every round for a variety of effects."
A12: Lunar Phase | B12: 1 | C12: Passive | D12: - | E12: - | F12: - | G12: Passive | H12: 1 | I12: Self | J12: - | K12: At the start of a game, the user picks a Phase. At the start of each turn, the user shifts between Phases in the following order: New Moon (+1 PE/ME) -> Waxing (+1 Range) -> Full Moon (Foes get -1 dice on attacks targeting the user) -> Waning (+1 Dice) -> New, etc. This passive cannot be disabled.
A13: Moonblast | B13: 1 | C13: Every Turn | D13: 3 | E13: 2d8+5 | F13: Magical | G13: Standard | H13: 1 | I13: Foe | J13: Range 3 | K13: The user's next phase effect is doubled.
A14: Lunar Shift | B14: 2 | C14: Twice/E2T | D14: - | E14: - | F14: - | G14: Free | H14: 1 | I14: Self | J14: - | K14: The user immediately moves to their next Lunar Phase. If Moonblast's effect is active it's transferred to the new phase.
A15: Holy Light | B15: 3 | C15: EoT | D15: 3 | E15: 1d8+10 | F15: Magical | G15: Standard | H15: 1 | I15: Foe | J15: Range 7 | K15: If the user is in Waxing, they gain +1 MP until the end of their next turn.
A16: Dark Reflection | B16: 4 | C16: EoT | D16: 4 | E16: 2d8+9 | F16: Magical | G16: Standard | H16: 1 | I16: Foe | J16: Range 4 | K16: Applies the inverse of the user's current phase effect to the target for one round.
A17: Harvest Moon | B17: 5 | C17: Every Turn | D17: 3 | E17: 2d10+6 | F17: Magical | G17: Standard | H17: 1 | I17: Foe | J17: Range 4 | K17: When used while in New Moon or Full Moon Phase, heal the user by 10% of the damage done.
A18: Tidal Wave | B18: 6 | C18: Twice | D18: 4 | E18: 3d8+7 | F18: Magical | G18: Standard | H18: AoE | I18: Foes | J18: Burst 1 | K18: Targets hit are moved one tile towards the user. This move is affected by the +Range from Waxing Phase.
A19: Tidal Locking | B19: 7 | C19: Twice | D19: 4 | E19: 2d10+7 | F19: Magical | G19: Standard | H19: 1 | I19: Foe | J19: Melee | K19: The user doesn't change phases at the start of their next turn. This move may be used as a non-damaging standard.
A20: Blood Moon | B20: 8 | C20: EoT | D20: 4 | E20: 2d8+6 | F20: Magical | G20: Standard | H20: 2 | I20: Foes | J20: Range 3 | K20: If the user is in Waxing or Waning, this move inflicts 5/1 Poison, otherwise it inflicts 5/1 Bleed.
A21: Celestial Blessing | B21: 9 | C21: Once | D21: - | E21: - | F21: - | G21: Free | H21: AoE | I21: Self and Allies | J21: Burst 1 | K21: All targets in range gain the effect of the user's next phase until the start of the user's next turn. Next turn, the user's phase has no effect, and phase-specific move effects cannot trigger. This is not affected by Moonblast.
A22: Gravity Crash | B22: 10 | C22: Once | D22: 4 | E22: 2d10+9 | F22: Magical | G22: Standard | H22: 1 | I22: Foe | J22: Melee | K22: This move has a different effect based on the phase it's used in: New Moon: The target is Sealed/1 Waxing (Push 2): If the target can't be pushed fully, they take 15 extra damage. Full Moon: All the target's AoE moves are single target for one round. Waning: This attack has bomb dice.
A23: Solar Rod
A24: 60 HP | 2 ATK | 14 MAG | 9 PD | 9 MD | 1 MP | G24: "Burn the opponent and benefit from their suffering."
A25: Sun Rays | B25: 1 | C25: Every Turn | D25: 2 | E25: 2d8+4 | F25: Magical | G25: Standard | H25: 1 | I25: Foe | J25: Homing 5 | K25: The target is inflicted with unremovable Burn 3/1.
A26: Searing Shot | B26: 2 | C26: EoT | D26: 3 | E26: 2d10+4 | F26: Magical | G26: Standard | H26: 1 | I26: Foe | J26: Range 3 | K26: The user's next attack gains +5 damage.
A27: Brilliant Flash | B27: 3 | C27: Twice/EoT | D27: 3 | E27: 2d10+7 | F27: Magical | G27: Standard | H27: AoE | I27: Foes | J27: Beam 2 | K27: Targets who are burned have their Burn extended by one round.
A28: Firestorm | B28: 4 | C28: E2T | D28: 4 | E28: 2d10+3 | F28: Magical | G28: Standard | H28: 2 | I28: Foes | J28: Homing 4 | K28: If one of the targets missed the user with an attack on their last turn, the user's next attack gains +X damage, where X = 3 * the MR of the attack that missed.
A29: Meteor Shower | B29: 5 | C29: Twice/EoT | D29: 4 | E29: 3d8+5 | F29: Magical | G29: Standard | H29: 1 | I29: Foe | J29: Homing 5 (Splash 1) | K29: For every target in range that is Burned, this attack gains a die.
A30: Radiant Dawn | B30: 6 | C30: E2T | D30: - | E30: - | F30: - | G30: Swift | H30: 1 | I30: Self or Foe | J30: Range 4 | K30: If used on a foe, the next time they are Burned, the burn damage is increased by 3. If used on self, the next time the user inflicts Burn, they heal the damage dealt by the burn whenever the foe takes it.
A31: Pyroclasm | B31: 7 | C31: Once | D31: 4 | E31: 1d6+2 | F31: Magical | G31: Standard | H31: 3 | I31: Foes | J31: Global | K31: All targets hit are inflicted with unremovable 3 Burn/1. This move and its burn are immune to outside factors. Do not add MAG to the roll.
A32: Supernova | B32: 8 | C32: Twice / EoT | D32: 4 | E32: 3d8+2 | F32: Magical | G32: Standard | H32: AoE | I32: Foes | J32: Star 2 | K32: Targets in Burst 1 are inflicted with unremovable 5 Burn/2. Other targets are inflicted with unremovable 5 Burn/1.
A33: Conflagration | B33: 9 | C33: Twice/EoT | D33: 4 | E33: 3d8+5 | F33: Magical | G33: Standard | H33: 1 | I33: Foe | J33: Melee | K33: If this attack has a damage buff from a Solar Rod move applied to it, double the additional damage dealt from it.
A34: Solar Flare | B34: 10 | C34: Once | D34: 5 | E34: 4d8+3 | F34: Magical | G34: Standard | H34: AoE | I34: Foes | J34: Pierce 4 | K34: This attack gains Bomb Dice if a target is burned.
A35: Star Rod
A36: 65 HP | 0 ATK | 11 MAG | 12 PD | 12 MD | 2 MP | G36: "A defensive weapon that controls and manipulates enemy movement."
A37: Geodesic | B37: 1 | C37: Passive | D37: - | E37: - | F37: - | G37: Passive | H37: - | I37: Self | J37: - | K37: The user takes 80% damage from attacks originating from their Range 3, and 10% more for every tile closer or farther away.
A38: Star Storm | B38: 1 | C38: Every Turn | D38: 3 | E38: 2d8+5 | F38: Magical | G38: Standard | H38: 1 | I38: Foe | J38: Range 5 (Splash 1) | K38: If the target(s), on their next turn, moves towards the user, this deals an additional 1d8 damage.
A39: Orbit | B39: 2 | C39: Twice/EoT | D39: 3 | E39: 1d8+0 | F39: Magical | G39: Standard | H39: AoE | I39: Foes | J39: Star 3 | K39: On their next turn, targets that perform attacks that do not target the user (if they are able to target the user) take 2d8+8 damage. Additionally, targets who end their next turn in the user's Range 3 take 2d8+8 damage.
A40: Cosmic Power | B40: 3 | C40: Twice/EoT | D40: 4 | E40: 3d6+7 | F40: Magical | G40: Standard | H40: 1 | I40: Foe | J40: Range 4 | K40: If the opponent is able to move to a different tile type before the end of their next turn, but doesn't, this deals an additional 1d8+10 damage and inflicts 6 Cripple/1.
A41: Focal Point | B41: 4 | C41: Every Turn | D41: - | E41: - | F41: - | G41: Trigger | H41: - | I41: Self | J41: - | K41: Gain either Exotic Star or Sequence Star until the start of the user's next turn. This move cannot be used while the user has a star active. Exotic Star: Whenever the user deals damage to a foe outside their melee, deal an additional 1d8 damage. If Exotic Star was also selected last turn, instead deal 1d4 additional damage. Sequence Star: Geodesic instead calculates based on Range 1. If Sequence Star was also selected last turn, Geodesic's base is 90%.
...

Sheet Clairvoyant
B1: Lvl | C1: Frequency | D1: MR | E1: Damage | H1: Target | K1: Effect
E2: Roll | F2: Type | G2: Action Type | H2: Amount | I2: Group | J2: Range and Modifiers
A3: Basic Abilities
A4: =Classes!A4 -> Basic Attack (P) / Basic Attack (M) | B4: =Classes!B4 -> B | C4: =Classes!C4 -> Every Turn | D4: =Classes!D4 -> 2 | E4: =Classes!E4 -> 1d10+2 | F4: =Classes!F4 -> Physical or Magical | G4: =Classes!G4 -> Standard | H4: =Classes!H4 -> 1 | ... K4: =Classes!K4 -> A basic attack. The user may choose either BATK (P) or BATK (M). Add the corresponding stat depending on their choice (BATK (P) = Physical Attack. BATK (M) = Magical Attack).This attack can be used even when sealed and its use cannot be prevented by any means, outside of Stun.
A5: =Classes!A5 -> Dash | B5: =Classes!B5 -> B | C5: =Classes!C5 -> Every Turn | D5: =Classes!D5 -> - | E5: =Classes!E5 -> - | F5: =Classes!F5 -> - | G5: =Classes!G5 -> Full | H5: =Classes!H5 -> - | ... K5: =Classes!K5 -> The user moves up to 1.5x their MP (rounded down) instead of 1x. (Dash is a Full action, which takes up both the Movement and Standard actions.)
A6: =Classes!A6 -> Backstep | B6: =Classes!B6 -> B | C6: =Classes!C6 -> Every Turn | D6: =Classes!D6 -> - | E6: =Classes!E6 -> - | F6: =Classes!F6 -> - | G6: =Classes!G6 -> Movement | H6: =Classes!H6 -> - | ... K6: =Classes!K6 -> This can only be used while a foe is in the user's Melee. The user moves one tile in a cardinal direction without triggering Attack of Opportunity.
A7: =Classes!A7 -> Attack of Opportunity | B7: =Classes!B7 -> B | C7: =Classes!C7 -> Every Turn | D7: =Classes!D7 -> 2 | E7: =Classes!E7 -> 1d10+2 | F7: =Classes!F7 -> Physical or Magical | G7: =Classes!G7 -> Reaction | H7: =Classes!H7 -> 1 | ... K7: =Classes!K7 -> This may be used when a foe in the user's Melee either: leaves that Melee with their Movement action, or uses a ranged attack that doesn't target the user (after damage is rolled). This Reaction still adds ATK or MAG.
A8: Clairvoyant Abilities
A10: Orb
A11: 60 HP | 7 ATK | 13 MAG | 5 PD | 16 MD | 1 MP | G11: "Delay your attacks to the future for enhanced effects."
A12: Future Sight | B12: 1 | C12: Passive | D12: - | E12: - | F12: - | G12: Passive | H12: - | I12: - | J12: - | K12: The user's Delay attacks always land if they hit, even if the user is dead. Delay: Delay moves have their damage and effects delayed for a specified number of rounds, landing at the start of the user's turn. Damage is rolled when the move is used, with damage altering effects applied on use
A13: Augur | B13: 1 | C13: Every Turn | D13: 3 | E13: 3d8+1 | F13: Magical | G13: Standard | H13: 1 | I13: Foe | J13: Homing 5 | K13: Before accuracy, the user may choose to give this move Delay-1 for an additional 5 damage or +3 Critical Range on this move, or Delay-2 for both.
A14: Echo Burst | B14: 2 | C14: Every Turn | D14: 3 | E14: 2d8+7 | F14: Magical | G14: Standard | H14: 1 | I14: Foe | J14: Homing 5 (Splash 1) | K14: Before accuracy, the user may choose to give this move Delay-1. If they do, it loses Splash, but the user gains +5 DR until the move deals damage.
A15: Scry | B15: 3 | C15: EoT | D15: 3 | E15: 2d8+4 | F15: Magical | G15: Standard | H15: AoE | I15: Foes | J15: Cone 2 | K15: The user gains +5 damage on their next attack. Before accuracy, the user may give this move Delay-1 to extend this attack's Cone by 1.
A16: Spirit Shackle | B16: 4 | C16: Twice/EoT | D16: 4 | E16: 1d8+3 | F16: Magical | G16: Standard | H16: 3 | I16: Foes | J16: Global | K16: This move has Delay-X, where X is the number of Foes hit. This move is immune to outside factors. This does not add MAG.
A17: Dawn Break | B17: 5 | C17: EoT | D17: 3 | E17: 1d8+9 | F17: Magical | G17: Standard | H17: 1 | I17: Foe | J17: Range 7 | K17: This ability has Delay-2. Until this ability lands, all of the user's attacks on the target have -1 MR. The user may increase the Delay by 1 for an additional -1 MR on the target.
A18: Prismatic Burst | B18: 6 | C18: E2T | D18: 4 | E18: 3d6+6 | F18: Magical | G18: Standard | H18: AoE | I18: Foes | J18: Burst 1 | K18: The user may choose to add Delay-X to this ability to give it +X dice, where X is the amount of targets hit.
A19: Omen | B19: 7 | C19: Once | D19: - | E19: - | F19: - | G19: Swift | H19: 1 | I19: Self | J19: - | K19: The user's next attack has an extra turn of delay with a doubled delay bonus.
A20: Foresight | B20: 7 | C20: Once | D20: - | E20: - | F20: - | G20: Reaction | H20: 1 | I20: Foe | J20: - | K20: This may be used when the user is attacked, after damage is rolled. 10% of the attack's damage is removed and added to all of the user's currently delayed attacks.
A21: Prophecy | B21: 8 | C21: Twice/EoT | D21: 4 | E21: 1d8+12 | F21: Magical | G21: Standard | H21: 1 | I21: Foe | J21: Homing 6 | K21: All the user's currently delayed moves land at the same time as this attack.
A22: Corruption | B22: 9 | C22: Twice/EoT | D22: 4 | E22: 3d8+6 | F22: Magical | G22: Standard | H22: 1 | I22: Foe | J22: Range 5 | K22: This attack inflicts 5 Poison/1 on hit. Before accuracy, the user may choose to give this move Delay-1 for extending the Poison duration by 1 round, or Delay-2 for +5 poison damage.
A23: Requite | B23: 10 | C23: Once | D23: 5 | E23: 3d8+11 | F23: Magical | G23: Standard | H23: 1 | I23: Foe | J23: Range 5 | K23: This move has Delay-1 and a Delay bonus of +10 damage if the user dies before this attack lands.
A24: Pendulum
A25: 65 HP | 5 ATK | 9 MAG | 12 PD | 9 MD | 1 MP | G25: "A control weapon that requires its opponents to use their abilities carefully."
A26: Oscillations | B26: 1 | C26: Passive | D26: - | E26: - | F26: - | G26: Passive | H26: - | I26: - | J26: - | K26: The user starts the game with one Momentum (max three). The user gains +1 MP per Momentum. Momentum can be spent even if the MP was used previously on their turn. Conditional out-of-turn damage effects of this weapon can trigger only once, excluding damage from statuses.
A27: Entrance | B27: 1 | C27: Every Turn | D27: 2 | E27: 2d10+3 | F27: Magical | G27: Standard | H27: 1 | I27: Foe | J27: Range 6 | K27: For one round, if the target uses a move on the user, the user gains one Momentum. This move can be used while Sealed.
A28: Torment | B28: 2 | C28: Every Turn | D28: 4 | E28: 5d4+3 | F28: Magical | G28: Standard | H28: 1 | I28: Foe | J28: Range 4 | K28: After accuracy, the user may spend 1 Momentum to either: extend the effect of their next Pendulum Standard/Full by one round (including status effects), or gain 2d8+1 advantage damage on their next Standard/Full attack.
A29: Action and Reaction | B29: 3 | C29: Twice/EoT | D29: - | E29: - | F29: - | G29: Trigger | H29: 1 | I29: Self | J29: - | K29: This can only be used at the start of the user's turn. The user permanently sacrifices 1 MP to increase their Momentum cap by 1 (preserving their Momentum stacks). Additionally, the user activates the ability to passively generate 1 Momentum after using a Standard/Full which targets a player (including self, except Dash), once per turn. Dowse is disabled for one round.
A30: Dowse | B30: 3 | C30: Every Turn | D30: - | E30: - | F30: - | G30: Trigger | H30: 1 | I30: Self | J30: - | K30: Once per turn, the user's next Standard/Full attack this turn unremovably gains advantage damage rolls & -2 DMG. Action and Reaction's passive Momentum generation is deactivated. (Dowse cannot trigger Amplifier).
A31: Hallucinations | B31: 4 | C31: E2T | D31: 3 | E31: Varies | F31: Magical | G31: Standard | H31: 1 | I31: Foe | J31: Range 4 | K31: Choose Dream or Nightmare. Dream: 5d6+1 damage roll. The user gains two Momentum, while the target gains +3 DR/1 or +3 DMG/1 (chosen by the user). Nightmare: 3d10+2 damage roll. For one round, if the target uses a Once/Twice/Thrice move, they take 3d8+5 damage. The user may spend 2 Momentum to inflict -25% damage on such attacks of the target for one round.
A32: Clacker Volley | B32: 5 | C32: EoT | D32: 3 | E32: 3d8+6 | F32: Magical | G32: Standard | H32: 2 | I32: Foes | J32: Line 3 (Push 1) | K32: Targets are inflicted with Confusion/1. If at least two targets have hit the user with Standard/Full attacks last round, one of the targets hit (chosen by the user) is also Sealed/1. The Seal's duration cannot be extended by Torment.
A33: Angular Momentum | B33: 6 | C33: Twice/EoT | D33: - | E33: - | F33: - | G33: Free | H33: 1 | I33: Self | J33: - | K33: The user spends Momentum to gain +2 EVA/1 for every two Momentum spent. One additional Momentum may be spent to extend this buff's duration to two rounds.
A34: Mass Hysteria | B34: 7 | C34: Twice/EoT | D34: 5 | E34: 6d6+2 | F34: Magical | G34: Full | H34: AoE | I34: Foes | J34: Cone 2 | K34: The user can spend 1 Momentum per effect to give this ability any combination of the following effects: - Make this attack Burst 2, - Use this move as a Standard (1 Momentum is refunded if it misses 2+ targets), - Reduce 2d4+3 DMG from the next Standard/Full attack of each target hit, - Inflict Confusion/2.
A35: Hypnotic Daze | B35: 8 | C35: Twice/E2T | D35: 4 | E35: 1d12+10 | F35: Magical | G35: Standard | H35: 1 | I35: Foe | J35: Range 4 | K35: If the target uses a non-Weapon/non-Basic move in the next two rounds, they take 3d6+3 bomb damage. At the cost of one Momentum, the target's Frees and Triggers become Swifts for one round. If Dowse was used this turn, this move has +1 ACC.
A36: Nihil | B36: 9 | C36: Once | D36: 4 | E36: 3d10+6 | F36: Magical | G36: Standard | H36: 1 | I36: Foe | J36: Homing 3 | K36: For one round, if the target fails to buff the user on their turn, they take 7d4+4 damage. While under this effect, the target may target foes in their Range 3 with moves that can normally buff Self and/or Allies.
A37: Shatter Psyche | B37: 10 | C37: Once | D37: 4 | E37: 4d8+6 | F37: Magical | G37: Standard | H37: 1 | I37: Foe | J37: Melee | K37: For one round, if the target deals 45+ damage on their turn, they take 4d8+6 damage. The user may spend X Momentum to decrease the required damage threshold by 6X.
A38: Tarot Cards
A39: 65 HP | 5 ATK | 11 MAG | 9 PD | 10 MD | 2 MP | G39: "A luck weapon - gamble on your attacks to give you a massive advantage... or disadvantage!"
A40: Discard | B40: 1 | C40: Every Turn | D40: 2 | E40: 2d8+5 | F40: Magical | G40: Standard | H40: 1 | I40: Foe | J40: Range 4 | K40: On an accuracy roll of 15+, the user gains 1 Discard stack. As a Reaction to an attack of a Foe within Range 4 after its accuracy roll, the user may spend one stack to give that attack -2 ACC.
A41: Maverick | B41: 2 | C41: EoT | D41: 3 | E41: 2d8+4 | F41: Magical | G41: Standard | H41: AoE | I41: Foes | J41: Pierce 3 | K41: By default, roll a d4 after rolling damage. This determines damage multiplication: 1 = 0.5x, 2 = 1x, 3 = 1.5x, 4 = 2x. The user may choose to not roll the d4 before damage.
...

Sheet Dark
A1: Name | B1: Lvl | C1: Frequency | D1: MR | E1: Damage | H1: Target | K1: Effect
E2: Roll | F2: Type | G2: Action Type | H2: Amount | I2: Group | J2: Range and Modifiers
A3: Basic Abilities
A4: =Classes!A4 -> Basic Attack (P) / Basic Attack (M) | B4: =Classes!B4 -> B | C4: =Classes!C4 -> Every Turn | D4: =Classes!D4 -> 2 | E4: =Classes!E4 -> 1d10+2 | F4: =Classes!F4 -> Physical or Magical | G4: =Classes!G4 -> Standard | H4: =Classes!H4 -> 1 | ... K4: =Classes!K4 -> A basic attack. The user may choose either BATK (P) or BATK (M). Add the corresponding stat depending on their choice (BATK (P) = Physical Attack. BATK (M) = Magical Attack).This attack can be used even when sealed and its use cannot be prevented by any means, outside of Stun.
A5: =Classes!A5 -> Dash | B5: =Classes!B5 -> B | C5: =Classes!C5 -> Every Turn | D5: =Classes!D5 -> - | E5: =Classes!E5 -> - | F5: =Classes!F5 -> - | G5: =Classes!G5 -> Full | H5: =Classes!H5 -> - | ... K5: =Classes!K5 -> The user moves up to 1.5x their MP (rounded down) instead of 1x. (Dash is a Full action, which takes up both the Movement and Standard actions.)
A6: =Classes!A6 -> Backstep | B6: =Classes!B6 -> B | C6: =Classes!C6 -> Every Turn | D6: =Classes!D6 -> - | E6: =Classes!E6 -> - | F6: =Classes!F6 -> - | G6: =Classes!G6 -> Movement | H6: =Classes!H6 -> - | ... K6: =Classes!K6 -> This can only be used while a foe is in the user's Melee. The user moves one tile in a cardinal direction without triggering Attack of Opportunity.
A7: =Classes!A7 -> Attack of Opportunity | B7: =Classes!B7 -> B | C7: =Classes!C7 -> Every Turn | D7: =Classes!D7 -> 2 | E7: =Classes!E7 -> 1d10+2 | F7: =Classes!F7 -> Physical or Magical | G7: =Classes!G7 -> Reaction | H7: =Classes!H7 -> 1 | ... K7: =Classes!K7 -> This may be used when a foe in the user's Melee either: leaves that Melee with their Movement action, or uses a ranged attack that doesn't target the user (after damage is rolled). This Reaction still adds ATK or MAG.
A8: Dark Abilities
A10: Athame
A11: 65 HP | 6 ATK | 7 MAG | 15 PD | 10 MD | 3 MP | G11: "Gradually sacrifice your own HP to permanently boost your damage with no limit."
A12: Crimson Pact | B12: 1 | C12: Passive | D12: - | E12: - | F12: - | G12: Passive | H12: - | I12: - | J12: - | K12: Whenever the user damages a foe, they sacrifice HP equal to 10% of the total damage the foe took, if able. Then, they gain permanent bonus damage equal to the damage they took. (Bonus damage is also gained through effect-derived CP.)
A13: Bloodrush | B13: 1 | C13: Every Turn | D13: 2 | E13: 2d8+5 | F13: Magical | G13: Standard | H13: 1 | I13: Foe | J13: Range 3 | K13: If this move is used in Melee range, before accuracy, the user gains +3 DMG and +1 MP for one round.
A14: Infusion | B14: 2 | C14: E2T | D14: 4 | E14: 1d10+8 | F14: Magical | G14: Standard | H14: AoE | I14: Foes | J14: Pierce 4 | K14: For one round, the user gains +DR equal to the amount of bonus damage gained from this attack with Crimson Pact.
